Workbook

Sheet CO 1
G1: Construction Contract CHANGE ORDER (CO)
A2: Project Name: | F2: FTW-336A | W2: DU Job #: | Z2: J101395 | AB2: CO #
A3: Contractor: | F3: TAR/TBI Construction | W3: DU PO #: | Z3: n/a | AB3: 1
B4: The Contractor shall furnish all labor, equipment and materials, and perform all work necessary to complete the work described herein and/or in the document(s) attached hereto. DO NOT start work under this CO until you receive a fully executed original (signed by Doyon Utilities), or a written Notice to Proceed.
B5: Description of Work: | V5: Time Change* | Z5: Price Change | AE5: Time | AF5: Time
B6: Reference | F6: Item Description | V6: Cal. Days** | Z6: U.S. Dollars** | AE6: Reductions | AF6: Increases
B7: 1 | F7: DCVR 7 Larger Manhole | Z7: 10393 | AE7: =IF(W7<0,W7,0) -> 0 | AF7: =IF(W7>0,W7,0) -> 0
B8: 2 | AE8: =IF(W8<0,W8,0) -> 0 | AF8: =IF(W8>0,W8,0) -> 0
AE9: =IF(W9<0,W9,0) -> 0 | AF9: =IF(W9>0,W9,0) -> 0
AE10: =IF(W10<0,W10,0) -> 0 | AF10: =IF(W10>0,W10,0) -> 0
AE11: =IF(W11<0,W11,0) -> 0 | AF11: =IF(W11>0,W11,0) -> 0
AE12: =IF(W12<0,W12,0) -> 0 | AF12: =IF(W12>0,W12,0) -> 0
AE13: =IF(W13<0,W13,0) -> 0 | AF13: =IF(W13>0,W13,0) -> 0
AE14: =IF(W14<0,W14,0) -> 0 | AF14: =IF(W14>0,W14,0) -> 0
AE15: =IF(W15<0,W15,0) -> 0 | AF15: =IF(W15>0,W15,0) -> 0
B16: * Time Changes are NOT cumulative; Net Time Change = largest increase + largest decrease. ** Value in parenthesis is negative; i.e., (time reduction) or ($ credit) | S16: Net Change: | W16: =MIN(AE7:AE15)+MAX(AF7:AF15) -> 0 | Z16: =SUM(Z7:AB15) -> 10393
B17: As a result of this Change Order: | K17: the Contract Completion Time is | S17: =IF(W16=0,"UNCHANGED,",IF(W16<0,"REDUCED","INCREASED")) -> UNCHANGED, | W17: =IF(W16=0,"",W16) | Y17: =IF(W16=0,"","Calendar Day(s),")
B18: and the Total Contract Price is | S18: =IF(Z16=0,"UNCHANGED.",IF(Z16<0,"REDUCED","INCREASED")) -> INCREASED | W18: =IF(Z16=0,"",Z16) -> 10393 | AA18: =IF(Z16<>0,".","") -> .
B19: The Total Adjusted Contract Price to date and the Adjusted Contract Completion Date are stated in the Contract Summary below.
B20: The Contractor hereby accepts the foregoing adjustment as a final and complete equitable adjustment in full accord and satisfaction of all past, present and future liability originating under any Article in the Contract by reason of the facts and circumstances giving rise to this Change Order. Except as hereby modified, all terms and conditions of said Contract, as heretofore modified, remain unchanged and in full force and effect.
C21: THIS CHANGE ORDER IS HEREBY ACCEPTED: | P21: RECOMMENDED BY:
C22: Contractor:
P24: Architect/Engineer | Z24: Date
P25: Wily F. Splain
C26: /
P27: Doyon Utilities Project Manager | Z27: Date
C28: Typed or Printed Name / Title | P28: ACCEPTED BY:
C30: Signature | K30: Date | P30: for Doyon Utilities | Z30: Date
B31: CONTRACT SUMMARY UPON EXECUTION OF THIS CHANGE ORDER:
B32: Original Contract Completion Date: | O32: Adjusted Contract Completion Date:
B33: Original Contract Amount: | K33: 746512 | O33: Previous Contract Total:
B34: Previous Additions: | K34: 0 | O34: =IF(Z16=0,"This Change Order:",IF(Z16<0,"This Change Order, DEDUCT:","This Change Order, ADD:")) -> This Change Order, ADD: | Y34: =Z16 -> 10393
B35: Previous Deductions: | K35: 0 | O35: Total Adjusted Contract Price to date: | Y35: =SUM(Y33:Y34) -> 10393

Sheet CO 2
G1: Construction Contract CHANGE ORDER (CO)
A2: Project Name: | F2: ='CO 1'!F2:AB2 -> FTW-336A | W2: DU Job #: | Z2: ='CO 1'!Z2:AA2 -> J101395 | AB2: CO #
A3: Contractor: | F3: ='CO 1'!F3:AB3 -> TAR/TBI Construction | W3: DU PO #: | Z3: ='CO 1'!Z3:AA3 -> n/a | AB3: 2
B4: The Contractor shall furnish all labor, equipment and materials, and perform all work necessary to complete the work described herein and/or in the document(s) attached hereto. DO NOT start work under this CO until you receive a fully executed original (signed by Doyon Utilities), or a written Notice to Proceed.
B5: Description of Work: | V5: Time Change* | Z5: Price Change | AE5: Time | AF5: Time
B6: Reference | F6: Item Description | V6: Cal. Days** | Z6: U.S. Dollars** | AE6: Reductions | AF6: Increases
AE7: =IF(W7<0,W7,0) -> 0 | AF7: =IF(W7>0,W7,0) -> 0
AE8: =IF(W8<0,W8,0) -> 0 | AF8: =IF(W8>0,W8,0) -> 0
AE9: =IF(W9<0,W9,0) -> 0 | AF9: =IF(W9>0,W9,0) -> 0
AE10: =IF(W10<0,W10,0) -> 0 | AF10: =IF(W10>0,W10,0) -> 0
AE11: =IF(W11<0,W11,0) -> 0 | AF11: =IF(W11>0,W11,0) -> 0
AE12: =IF(W12<0,W12,0) -> 0 | AF12: =IF(W12>0,W12,0) -> 0
AE13: =IF(W13<0,W13,0) -> 0 | AF13: =IF(W13>0,W13,0) -> 0
AE14: =IF(W14<0,W14,0) -> 0 | AF14: =IF(W14>0,W14,0) -> 0
AE15: =IF(W15<0,W15,0) -> 0 | AF15: =IF(W15>0,W15,0) -> 0
B16: * Time Changes are NOT cumulative; Net Time Change = largest increase + largest decrease. ** Value in parenthesis is negative; i.e., (time reduction) or ($ credit) | S16: Net Change: | W16: =MIN(AE7:AE15)+MAX(AF7:AF15) -> 0 | Z16: =SUM(Z7:AB15) -> 0
B17: As a result of this Change Order: | K17: the Contract Completion Time is | S17: =IF(W16=0,"UNCHANGED,",IF(W16<0,"REDUCED","INCREASED")) -> UNCHANGED, | W17: =IF(W16=0,"",W16) | Y17: =IF(W16=0,"","Calendar Day(s),")
B18: and the Total Contract Price is | S18: =IF(Z16=0,"UNCHANGED.",IF(Z16<0,"REDUCED","INCREASED")) -> UNCHANGED. | W18: =IF(Z16=0,"",Z16) | AA18: =IF(Z16<>0,".","")
B19: The Total Adjusted Contract Price to date and the Adjusted Contract Completion Date are stated in the Contract Summary below.
B20: The Contractor hereby accepts the foregoing adjustment as a final and complete equitable adjustment in full accord and satisfaction of all past, present and future liability originating under any Article in the Contract by reason of the facts and circumstances giving rise to this Change Order. Except as hereby modified, all terms and conditions of said Contract, as heretofore modified, remain unchanged and in full force and effect.
C21: THIS CHANGE ORDER IS HEREBY ACCEPTED: | P21: RECOMMENDED BY:
C22: Contractor:
C24: =F3 -> TAR/TBI Construction | P24: Architect/Engineer | Z24: Date
C26: /
P27: Doyon Utilities Project Manager | Z27: Date
C28: Typed or Printed Name / Title | P28: ACCEPTED BY:
C30: Signature | K30: Date | P30: for Doyon Utilities | Z30: Date
B31: CONTRACT SUMMARY UPON EXECUTION OF THIS CHANGE ORDER:
B32: Previous Contract Completion Date: | K32: ='CO 1'!Y32 -> 0 | O32: Adjusted Contract Completion Date: | Y32: =IF(K32>0,K32+W16,"")
B33: Original Contract Amount: | K33: ='CO 1'!K33:N33 -> 746512 | O33: Previous Contract Total: | Y33: =SUM(F33:K35) -> 756905
B34: Previous Additions: | K34: =H39 -> 10393 | O34: =IF(Z16=0,"This Change Order:",IF(Z16<0,"This Change Order, DEDUCT:","This Change Order, ADD:")) -> This Change Order: | Y34: =Z16 -> 0
B35: Previous Deductions: | K35: =M39 -> 0 | O35: Total Adjusted Contract Price to date: | Y35: =SUM(Y33:Y34) -> 756905
F37: Summary of Previous Change Orders
H38: Price Additions | M38: Price Deductions | Q38: Net Time Change (Days)
F39: Totals: | H39: =SUM(H40:H40) -> 10393 | M39: =SUM(M40:M40) -> 0 | S39: =SUM(S40) -> 0
F40: CO | G40: 1 | H40: =IF('CO 1'!Z16>0,'CO 1'!Z16,"") -> 10393 | M40: =IF('CO 1'!Z16<0,'CO 1'!Z16,"") | S40: ='CO 1'!W16 -> 0

Sheet CO 3
Q1: CHANGE ORDER (CO)
A2: Project Name: | F2: ='CO 1'!F2:AB2 -> FTW-336A | W2: DU Job #: | Z2: ='CO 1'!Z2:AA2 -> J101395 | AB2: CO #
A3: Contractor: | F3: ='CO 1'!F3:AB3 -> TAR/TBI Construction | W3: DU PO #: | Z3: ='CO 1'!Z3:AA3 -> n/a | AB3: 3
B4: The Contractor shall furnish all labor, equipment and materials, and perform all work necessary to complete the work described herein and/or in the document(s) attached hereto. DO NOT start work under this CO until you receive a fully executed original (signed by Doyon Utilities), or a written Notice to Proceed.
B5: Description of Work: | V5: Time Change* | Z5: Price Change | AE5: Time | AF5: Time
B6: Reference | F6: Item Description | V6: Cal. Days** | Z6: U.S. Dollars** | AE6: Reductions | AF6: Increases
AE7: =IF(W7<0,W7,0) -> 0 | AF7: =IF(W7>0,W7,0) -> 0
AE8: =IF(W8<0,W8,0) -> 0 | AF8: =IF(W8>0,W8,0) -> 0
AE9: =IF(W9<0,W9,0) -> 0 | AF9: =IF(W9>0,W9,0) -> 0
AE10: =IF(W10<0,W10,0) -> 0 | AF10: =IF(W10>0,W10,0) -> 0
AE11: =IF(W11<0,W11,0) -> 0 | AF11: =IF(W11>0,W11,0) -> 0
AE12: =IF(W12<0,W12,0) -> 0 | AF12: =IF(W12>0,W12,0) -> 0
AE13: =IF(W13<0,W13,0) -> 0 | AF13: =IF(W13>0,W13,0) -> 0
AE14: =IF(W14<0,W14,0) -> 0 | AF14: =IF(W14>0,W14,0) -> 0
AE15: =IF(W15<0,W15,0) -> 0 | AF15: =IF(W15>0,W15,0) -> 0
B16: * Time Changes are NOT cumulative; Net Time Change = largest increase + largest decrease. ** Value in parenthesis is negative; i.e., (time reduction) or ($ credit) | S16: Net Change: | W16: =MIN(AE7:AE15)+MAX(AF7:AF15) -> 0 | Z16: =SUM(Z7:AB15) -> 0
B17: As a result of this Change Order: | K17: the Contract Completion Time is | S17: =IF(W16=0,"UNCHANGED,",IF(W16<0,"REDUCED","INCREASED")) -> UNCHANGED, | W17: =IF(W16=0,"",W16) | Y17: =IF(W16=0,"","Calendar Day(s),")
B18: and the Total Contract Price is | S18: =IF(Z16=0,"UNCHANGED.",IF(Z16<0,"REDUCED","INCREASED")) -> UNCHANGED. | W18: =IF(Z16=0,"",Z16) | AA18: =IF(Z16<>0,".","")
B19: The Total Adjusted Contract Price to date and the Adjusted Contract Completion Date are stated in the Contract Summary below.
B20: The Contractor hereby accepts the foregoing adjustment as a final and complete equitable adjustment in full accord and satisfaction of all past, present and future liability originating under any Article in the Contract by reason of the facts and circumstances giving rise to this Change Order. Except as hereby modified, all terms and conditions of said Contract, as heretofore modified, remain unchanged and in full force and effect.
C21: THIS CHANGE ORDER IS HEREBY ACCEPTED: | P21: RECOMMENDED BY:
C22: Contractor:
C24: =F3 -> TAR/TBI Construction | P24: Architect/Engineer | Z24: Date
C26: /
P27: Doyon Utilities Project Manager | Z27: Date
C28: Typed or Printed Name / Title | P28: ACCEPTED BY:
C30: Signature | K30: Date | P30: for Doyon Utilities | Z30: Date
B31: CONTRACT SUMMARY UPON EXECUTION OF THIS CHANGE ORDER:
B32: Previous Contract Completion Date: | K32: ='CO 2'!Y32 | O32: Adjusted Contract Completion Date: | Y32: =IF(K32>0,K32+W16,"")
B33: Original Contract Amount: | K33: ='CO 1'!K33:N33 -> 746512 | O33: Previous Contract Total: | Y33: =SUM(F33:K35) -> 756905
B34: Previous Additions: | K34: =H39 -> 10393 | O34: =IF(Z16=0,"This Change Order:",IF(Z16<0,"This Change Order, DEDUCT:","This Change Order, ADD:")) -> This Change Order: | Y34: =Z16 -> 0
B35: Previous Deductions: | K35: =M39 -> 0 | O35: Total Adjusted Contract Price to date: | Y35: =SUM(Y33:Y34) -> 756905
F37: Summary of Previous Change Orders
H38: Price Additions | M38: Price Deductions | Q38: Net Time Change (Days)
F39: Totals: | H39: =SUM(H40:H41) -> 10393 | M39: =SUM(M40:M41) -> 0 | S39: =SUM(S40:S41) -> 0
F40: CO | G40: 1 | H40: =IF('CO 1'!Z16>0,'CO 1'!Z16,"") -> 10393 | M40: =IF('CO 1'!Z16<0,'CO 1'!Z16,"") | S40: ='CO 1'!W16 -> 0
F41: CO | G41: 2 | H41: =IF('CO 2'!Z16>0,'CO 2'!Z16,"") | M41: =IF('CO 2'!Z16<0,'CO 2'!Z16,"") | S41: ='CO 2'!W16 -> 0

Sheet CO 4
Q1: CHANGE ORDER (CO)
A2: Project Name: | F2: ='CO 1'!F2:AB2 -> FTW-336A | W2: DU Job #: | Z2: ='CO 1'!Z2:AA2 -> J101395 | AB2: CO #
A3: Contractor: | F3: ='CO 1'!F3:AB3 -> TAR/TBI Construction | W3: DU PO #: | Z3: ='CO 1'!Z3:AA3 -> n/a | AB3: 4
B4: The Contractor shall furnish all labor, equipment and materials, and perform all work necessary to complete the work described herein and/or in the document(s) attached hereto. DO NOT start work under this CO until you receive a fully executed original (signed by Doyon Utilities), or a written Notice to Proceed.
B5: Description of Work: | V5: Time Change* | Z5: Price Change | AE5: Time | AF5: Time
B6: Reference | F6: Item Description | V6: Cal. Days** | Z6: U.S. Dollars** | AE6: Reductions | AF6: Increases
AE7: =IF(W7<0,W7,0) -> 0 | AF7: =IF(W7>0,W7,0) -> 0
AE8: =IF(W8<0,W8,0) -> 0 | AF8: =IF(W8>0,W8,0) -> 0
AE9: =IF(W9<0,W9,0) -> 0 | AF9: =IF(W9>0,W9,0) -> 0
AE10: =IF(W10<0,W10,0) -> 0 | AF10: =IF(W10>0,W10,0) -> 0
AE11: =IF(W11<0,W11,0) -> 0 | AF11: =IF(W11>0,W11,0) -> 0
AE12: =IF(W12<0,W12,0) -> 0 | AF12: =IF(W12>0,W12,0) -> 0
AE13: =IF(W13<0,W13,0) -> 0 | AF13: =IF(W13>0,W13,0) -> 0
AE14: =IF(W14<0,W14,0) -> 0 | AF14: =IF(W14>0,W14,0) -> 0
AE15: =IF(W15<0,W15,0) -> 0 | AF15: =IF(W15>0,W15,0) -> 0
B16: * Time Changes are NOT cumulative; Net Time Change = largest increase + largest decrease. ** Value in parenthesis is negative; i.e., (time reduction) or ($ credit) | S16: Net Change: | W16: =MIN(AE7:AE15)+MAX(AF7:AF15) -> 0 | Z16: =SUM(Z7:AB15) -> 0
B17: As a result of this Change Order: | K17: the Contract Completion Time is | S17: =IF(W16=0,"UNCHANGED,",IF(W16<0,"REDUCED","INCREASED")) -> UNCHANGED, | W17: =IF(W16=0,"",W16) | Y17: =IF(W16=0,"","Calendar Day(s),")
B18: and the Total Contract Price is | S18: =IF(Z16=0,"UNCHANGED.",IF(Z16<0,"REDUCED","INCREASED")) -> UNCHANGED. | W18: =IF(Z16=0,"",Z16) | AA18: =IF(Z16<>0,".","")
B19: The Total Adjusted Contract Price to date and the Adjusted Contract Completion Date are stated in the Contract Summary below.
B20: The Contractor hereby accepts the foregoing adjustment as a final and complete equitable adjustment in full accord and satisfaction of all past, present and future liability originating under any Article in the Contract by reason of the facts and circumstances giving rise to this Change Order. Except as hereby modified, all terms and conditions of said Contract, as heretofore modified, remain unchanged and in full force and effect.
C21: THIS CHANGE ORDER IS HEREBY ACCEPTED: | P21: RECOMMENDED BY:
C22: Contractor:
C24: =F3 -> TAR/TBI Construction | P24: Architect/Engineer | Z24: Date
C26: /
P27: Doyon Utilities Project Manager | Z27: Date
C28: Typed or Printed Name / Title | P28: ACCEPTED BY:
C30: Signature | K30: Date | P30: for Doyon Utilities | Z30: Date
B31: CONTRACT SUMMARY UPON EXECUTION OF THIS CHANGE ORDER:
B32: Previous Contract Completion Date: | K32: ='CO 3'!Y32 | O32: Adjusted Contract Completion Date: | Y32: =IF(K32>0,K32+W16,"")
B33: Original Contract Amount: | K33: ='CO 1'!K33:N33 -> 746512 | O33: Previous Contract Total: | Y33: =SUM(F33:K35) -> 756905
B34: Previous Additions: | K34: =H39 -> 10393 | O34: =IF(Z16=0,"This Change Order:",IF(Z16<0,"This Change Order, DEDUCT:","This Change Order, ADD:")) -> This Change Order: | Y34: =Z16 -> 0
B35: Previous Deductions: | K35: =M39 -> 0 | O35: Total Adjusted Contract Price to date: | Y35: =SUM(Y33:Y34) -> 756905
F37: Summary of Previous Change Orders
H38: Price Additions | M38: Price Deductions | Q38: Net Time Change (Days)
F39: Totals: | H39: =SUM(H40:H42) -> 10393 | M39: =SUM(M40:M42) -> 0 | S39: =SUM(S40:S42) -> 0
F40: CO | G40: 1 | H40: =IF('CO 1'!Z16>0,'CO 1'!Z16,"") -> 10393 | M40: =IF('CO 1'!Z16<0,'CO 1'!Z16,"") | S40: ='CO 1'!W16 -> 0
F41: CO | G41: 2 | H41: =IF('CO 2'!Z16>0,'CO 2'!Z16,"") | M41: =IF('CO 2'!Z16<0,'CO 2'!Z16,"") | S41: ='CO 2'!W16 -> 0
F42: CO | G42: 3 | H42: =IF('CO 3'!Z16>0,'CO 3'!Z16,"") | M42: =IF('CO 3'!Z16<0,'CO 3'!Z16,"") | S42: ='CO 3'!W16 -> 0

Sheet CO 5
Q1: CHANGE ORDER (CO)
A2: Project Name: | F2: ='CO 1'!F2:AB2 -> FTW-336A | W2: DU Job #: | Z2: ='CO 1'!Z2:AA2 -> J101395 | AB2: CO #
A3: Contractor: | F3: ='CO 1'!F3:AB3 -> TAR/TBI Construction | W3: DU PO #: | Z3: ='CO 1'!Z3:AA3 -> n/a | AB3: 5
B4: The Contractor shall furnish all labor, equipment and materials, and perform all work necessary to complete the work described herein and/or in the document(s) attached hereto. DO NOT start work under this CO until you receive a fully executed original (signed by Doyon Utilities), or a written Notice to Proceed.
B5: Description of Work: | V5: Time Change* | Z5: Price Change | AE5: Time | AF5: Time
B6: Reference | F6: Item Description | V6: Cal. Days** | Z6: U.S. Dollars** | AE6: Reductions | AF6: Increases
AE7: =IF(W7<0,W7,0) -> 0 | AF7: =IF(W7>0,W7,0) -> 0
AE8: =IF(W8<0,W8,0) -> 0 | AF8: =IF(W8>0,W8,0) -> 0
AE9: =IF(W9<0,W9,0) -> 0 | AF9: =IF(W9>0,W9,0) -> 0
AE10: =IF(W10<0,W10,0) -> 0 | AF10: =IF(W10>0,W10,0) -> 0
AE11: =IF(W11<0,W11,0) -> 0 | AF11: =IF(W11>0,W11,0) -> 0
AE12: =IF(W12<0,W12,0) -> 0 | AF12: =IF(W12>0,W12,0) -> 0
AE13: =IF(W13<0,W13,0) -> 0 | AF13: =IF(W13>0,W13,0) -> 0
AE14: =IF(W14<0,W14,0) -> 0 | AF14: =IF(W14>0,W14,0) -> 0
AE15: =IF(W15<0,W15,0) -> 0 | AF15: =IF(W15>0,W15,0) -> 0
B16: * Time Changes are NOT cumulative; Net Time Change = largest increase + largest decrease. ** Value in parenthesis is negative; i.e., (time reduction) or ($ credit) | S16: Net Change: | W16: =MIN(AE7:AE15)+MAX(AF7:AF15) -> 0 | Z16: =SUM(Z7:AB15) -> 0
B17: As a result of this Change Order: | K17: the Contract Completion Time is | S17: =IF(W16=0,"UNCHANGED,",IF(W16<0,"REDUCED","INCREASED")) -> UNCHANGED, | W17: =IF(W16=0,"",W16) | Y17: =IF(W16=0,"","Calendar Day(s),")
B18: and the Total Contract Price is | S18: =IF(Z16=0,"UNCHANGED.",IF(Z16<0,"REDUCED","INCREASED")) -> UNCHANGED. | W18: =IF(Z16=0,"",Z16) | AA18: =IF(Z16<>0,".","")
B19: The Total Adjusted Contract Price to date and the Adjusted Contract Completion Date are stated in the Contract Summary below.
B20: The Contractor hereby accepts the foregoing adjustment as a final and complete equitable adjustment in full accord and satisfaction of all past, present and future liability originating under any Article in the Contract by reason of the facts and circumstances giving rise to this Change Order. Except as hereby modified, all terms and conditions of said Contract, as heretofore modified, remain unchanged and in full force and effect.
C21: THIS CHANGE ORDER IS HEREBY ACCEPTED: | P21: RECOMMENDED BY:
C22: Contractor:
C24: =F3 -> TAR/TBI Construction | P24: Architect/Engineer | Z24: Date
C26: /
P27: Doyon Utilities Project Manager | Z27: Date
C28: Typed or Printed Name / Title | P28: ACCEPTED BY:
C30: Signature | K30: Date | P30: for Doyon Utilities | Z30: Date
B31: CONTRACT SUMMARY UPON EXECUTION OF THIS CHANGE ORDER:
B32: Previous Contract Completion Date: | K32: ='CO 4'!Y32 | O32: Adjusted Contract Completion Date: | Y32: =IF(K32>0,K32+W16,"")
B33: Original Contract Amount: | K33: ='CO 1'!K33:N33 -> 746512 | O33: Previous Contract Total: | Y33: =SUM(F33:K35) -> 756905
B34: Previous Additions: | K34: =H39 -> 10393 | O34: =IF(Z16=0,"This Change Order:",IF(Z16<0,"This Change Order, DEDUCT:","This Change Order, ADD:")) -> This Change Order: | Y34: =Z16 -> 0
B35: Previous Deductions: | K35: =M39 -> 0 | O35: Total Adjusted Contract Price to date: | Y35: =SUM(Y33:Y34) -> 756905
F37: Summary of Previous Change Orders
H38: Price Additions | M38: Price Deductions | Q38: Net Time Change (Days)
F39: Totals: | H39: =SUM(H40:H43) -> 10393 | M39: =SUM(M40:M43) -> 0 | S39: =SUM(S40:S43) -> 0
F40: CO | G40: 1 | H40: =IF('CO 1'!Z16>0,'CO 1'!Z16,"") -> 10393 | M40: =IF('CO 1'!Z16<0,'CO 1'!Z16,"") | S40: ='CO 1'!W16 -> 0
F41: CO | G41: 2 | H41: =IF('CO 2'!Z16>0,'CO 2'!Z16,"") | M41: =IF('CO 2'!Z16<0,'CO 2'!Z16,"") | S41: ='CO 2'!W16 -> 0
F42: CO | G42: 3 | H42: =IF('CO 3'!Z16>0,'CO 3'!Z16,"") | M42: =IF('CO 3'!Z16<0,'CO 3'!Z16,"") | S42: ='CO 3'!W16 -> 0
F43: CO | G43: 4 | H43: =IF('CO 4'!Z16>0,'CO 4'!Z16,"") | M43: =IF('CO 4'!Z16<0,'CO 4'!Z16,"") | S43: ='CO 4'!W16 -> 0

Sheet CO 6
Q1: CHANGE ORDER (CO)
A2: Project Name: | F2: ='CO 1'!F2:AB2 -> FTW-336A | W2: DU Job #: | Z2: ='CO 1'!Z2:AA2 -> J101395 | AB2: CO #
A3: Contractor: | F3: ='CO 1'!F3:AB3 -> TAR/TBI Construction | W3: DU PO #: | Z3: ='CO 1'!Z3:AA3 -> n/a | AB3: 6
B4: The Contractor shall furnish all labor, equipment and materials, and perform all work necessary to complete the work described herein and/or in the document(s) attached hereto. DO NOT start work under this CO until you receive a fully executed original (signed by Doyon Utilities), or a written Notice to Proceed.
B5: Description of Work: | V5: Time Change* | Z5: Price Change | AE5: Time | AF5: Time
B6: Reference | F6: Item Description | V6: Cal. Days** | Z6: U.S. Dollars** | AE6: Reductions | AF6: Increases
AE7: =IF(W7<0,W7,0) -> 0 | AF7: =IF(W7>0,W7,0) -> 0
AE8: =IF(W8<0,W8,0) -> 0 | AF8: =IF(W8>0,W8,0) -> 0
AE9: =IF(W9<0,W9,0) -> 0 | AF9: =IF(W9>0,W9,0) -> 0
AE10: =IF(W10<0,W10,0) -> 0 | AF10: =IF(W10>0,W10,0) -> 0
AE11: =IF(W11<0,W11,0) -> 0 | AF11: =IF(W11>0,W11,0) -> 0
AE12: =IF(W12<0,W12,0) -> 0 | AF12: =IF(W12>0,W12,0) -> 0
AE13: =IF(W13<0,W13,0) -> 0 | AF13: =IF(W13>0,W13,0) -> 0
AE14: =IF(W14<0,W14,0) -> 0 | AF14: =IF(W14>0,W14,0) -> 0
AE15: =IF(W15<0,W15,0) -> 0 | AF15: =IF(W15>0,W15,0) -> 0
B16: * Time Changes are NOT cumulative; Net Time Change = largest increase + largest decrease. ** Value in parenthesis is negative; i.e., (time reduction) or ($ credit) | S16: Net Change: | W16: =MIN(AE7:AE15)+MAX(AF7:AF15) -> 0 | Z16: =SUM(Z7:AB15) -> 0
B17: As a result of this Change Order: | K17: the Contract Completion Time is | S17: =IF(W16=0,"UNCHANGED,",IF(W16<0,"REDUCED","INCREASED")) -> UNCHANGED, | W17: =IF(W16=0,"",W16) | Y17: =IF(W16=0,"","Calendar Day(s),")
B18: and the Total Contract Price is | S18: =IF(Z16=0,"UNCHANGED.",IF(Z16<0,"REDUCED","INCREASED")) -> UNCHANGED. | W18: =IF(Z16=0,"",Z16) | AA18: =IF(Z16<>0,".","")
B19: The Total Adjusted Contract Price to date and the Adjusted Contract Completion Date are stated in the Contract Summary below.
B20: The Contractor hereby accepts the foregoing adjustment as a final and complete equitable adjustment in full accord and satisfaction of all past, present and future liability originating under any Article in the Contract by reason of the facts and circumstances giving rise to this Change Order. Except as hereby modified, all terms and conditions of said Contract, as heretofore modified, remain unchanged and in full force and effect.
C21: THIS CHANGE ORDER IS HEREBY ACCEPTED: | P21: RECOMMENDED BY:
C22: Contractor:
C24: =F3 -> TAR/TBI Construction | P24: Architect/Engineer | Z24: Date
C26: /
P27: Doyon Utilities Project Manager | Z27: Date
C28: Typed or Printed Name / Title | P28: ACCEPTED BY:
C30: Signature | K30: Date | P30: for Doyon Utilities | Z30: Date
B31: CONTRACT SUMMARY UPON EXECUTION OF THIS CHANGE ORDER:
B32: Previous Contract Completion Date: | K32: ='CO 5'!Y32 | O32: Adjusted Contract Completion Date: | Y32: =IF(K32>0,K32+W16,"")
B33: Original Contract Amount: | K33: ='CO 1'!K33:N33 -> 746512 | O33: Previous Contract Total: | Y33: =SUM(F33:K35) -> 756905
B34: Previous Additions: | K34: =H39 -> 10393 | O34: =IF(Z16=0,"This Change Order:",IF(Z16<0,"This Change Order, DEDUCT:","This Change Order, ADD:")) -> This Change Order: | Y34: =Z16 -> 0
B35: Previous Deductions: | K35: =M39 -> 0 | O35: Total Adjusted Contract Price to date: | Y35: =SUM(Y33:Y34) -> 756905
F37: Summary of Previous Change Orders
H38: Price Additions | M38: Price Deductions | Q38: Net Time Change (Days)
F39: Totals: | H39: =SUM(H40:H44) -> 10393 | M39: =SUM(M40:M44) -> 0 | S39: =SUM(S40:S44) -> 0
F40: CO | G40: 1 | H40: =IF('CO 1'!Z16>0,'CO 1'!Z16,"") -> 10393 | M40: =IF('CO 1'!Z16<0,'CO 1'!Z16,"") | S40: ='CO 1'!W16 -> 0
F41: CO | G41: 2 | H41: =IF('CO 2'!Z16>0,'CO 2'!Z16,"") | M41: =IF('CO 2'!Z16<0,'CO 2'!Z16,"") | S41: ='CO 2'!W16 -> 0
F42: CO | G42: 3 | H42: =IF('CO 3'!Z16>0,'CO 3'!Z16,"") | M42: =IF('CO 3'!Z16<0,'CO 3'!Z16,"") | S42: ='CO 3'!W16 -> 0
F43: CO | G43: 4 | H43: =IF('CO 4'!Z16>0,'CO 4'!Z16,"") | M43: =IF('CO 4'!Z16<0,'CO 4'!Z16,"") | S43: ='CO 4'!W16 -> 0
F44: CO | G44: 5 | H44: =IF('CO 5'!Z16>0,'CO 5'!Z16,"") | M44: =IF('CO 5'!Z16<0,'CO 5'!Z16,"") | S44: ='CO 5'!W16 -> 0

Sheet CO 7
Q1: CHANGE ORDER (CO)
A2: Project Name: | F2: ='CO 1'!F2:AB2 -> FTW-336A | W2: DU Job #: | Z2: ='CO 1'!Z2:AA2 -> J101395 | AB2: CO #
A3: Contractor: | F3: ='CO 1'!F3:AB3 -> TAR/TBI Construction | W3: DU PO #: | Z3: ='CO 1'!Z3:AA3 -> n/a | AB3: 7
B4: The Contractor shall furnish all labor, equipment and materials, and perform all work necessary to complete the work described herein and/or in the document(s) attached hereto. DO NOT start work under this CO until you receive a fully executed original (signed by Doyon Utilities), or a written Notice to Proceed.
B5: Description of Work: | V5: Time Change* | Z5: Price Change | AE5: Time | AF5: Time
B6: Reference | F6: Item Description | V6: Cal. Days** | Z6: U.S. Dollars** | AE6: Reductions | AF6: Increases
AE7: =IF(W7<0,W7,0) -> 0 | AF7: =IF(W7>0,W7,0) -> 0
AE8: =IF(W8<0,W8,0) -> 0 | AF8: =IF(W8>0,W8,0) -> 0
AE9: =IF(W9<0,W9,0) -> 0 | AF9: =IF(W9>0,W9,0) -> 0
AE10: =IF(W10<0,W10,0) -> 0 | AF10: =IF(W10>0,W10,0) -> 0
AE11: =IF(W11<0,W11,0) -> 0 | AF11: =IF(W11>0,W11,0) -> 0
AE12: =IF(W12<0,W12,0) -> 0 | AF12: =IF(W12>0,W12,0) -> 0
AE13: =IF(W13<0,W13,0) -> 0 | AF13: =IF(W13>0,W13,0) -> 0
AE14: =IF(W14<0,W14,0) -> 0 | AF14: =IF(W14>0,W14,0) -> 0
AE15: =IF(W15<0,W15,0) -> 0 | AF15: =IF(W15>0,W15,0) -> 0
B16: * Time Changes are NOT cumulative; Net Time Change = largest increase + largest decrease. ** Value in parenthesis is negative; i.e., (time reduction) or ($ credit) | S16: Net Change: | W16: =MIN(AE7:AE15)+MAX(AF7:AF15) -> 0 | Z16: =SUM(Z7:AB15) -> 0
B17: As a result of this Change Order: | K17: the Contract Completion Time is | S17: =IF(W16=0,"UNCHANGED,",IF(W16<0,"REDUCED","INCREASED")) -> UNCHANGED, | W17: =IF(W16=0,"",W16) | Y17: =IF(W16=0,"","Calendar Day(s),")
B18: and the Total Contract Price is | S18: =IF(Z16=0,"UNCHANGED.",IF(Z16<0,"REDUCED","INCREASED")) -> UNCHANGED. | W18: =IF(Z16=0,"",Z16) | AA18: =IF(Z16<>0,".","")
B19: The Total Adjusted Contract Price to date and the Adjusted Contract Completion Date are stated in the Contract Summary below.
B20: The Contractor hereby accepts the foregoing adjustment as a final and complete equitable adjustment in full accord and satisfaction of all past, present and future liability originating under any Article in the Contract by reason of the facts and circumstances giving rise to this Change Order. Except as hereby modified, all terms and conditions of said Contract, as heretofore modified, remain unchanged and in full force and effect.
C21: THIS CHANGE ORDER IS HEREBY ACCEPTED: | P21: RECOMMENDED BY:
C22: Contractor:
C24: =F3 -> TAR/TBI Construction | P24: Architect/Engineer | Z24: Date
C26: /
P27: Doyon Utilities Project Manager | Z27: Date
C28: Typed or Printed Name / Title | P28: ACCEPTED BY:
C30: Signature | K30: Date | P30: for Doyon Utilities | Z30: Date
B31: CONTRACT SUMMARY UPON EXECUTION OF THIS CHANGE ORDER:
B32: Previous Contract Completion Date: | K32: ='CO 6'!Y32 | O32: Adjusted Contract Completion Date: | Y32: =IF(K32>0,K32+W16,"")
B33: Original Contract Amount: | K33: ='CO 1'!K33:N33 -> 746512 | O33: Previous Contract Total: | Y33: =SUM(F33:K35) -> 756905
B34: Previous Additions: | K34: =H39 -> 10393 | O34: =IF(Z16=0,"This Change Order:",IF(Z16<0,"This Change Order, DEDUCT:","This Change Order, ADD:")) -> This Change Order: | Y34: =Z16 -> 0
B35: Previous Deductions: | K35: =M39 -> 0 | O35: Total Adjusted Contract Price to date: | Y35: =SUM(Y33:Y34) -> 756905
F37: Summary of Previous Change Orders
H38: Price Additions | M38: Price Deductions | Q38: Net Time Change (Days)
F39: Totals: | H39: =SUM(H40:H45) -> 10393 | M39: =SUM(M40:M45) -> 0 | S39: =SUM(S40:S45) -> 0
F40: CO | G40: 1 | H40: =IF('CO 1'!Z16>0,'CO 1'!Z16,"") -> 10393 | M40: =IF('CO 1'!Z16<0,'CO 1'!Z16,"") | S40: ='CO 1'!W16 -> 0
F41: CO | G41: 2 | H41: =IF('CO 2'!Z16>0,'CO 2'!Z16,"") | M41: =IF('CO 2'!Z16<0,'CO 2'!Z16,"") | S41: ='CO 2'!W16 -> 0
F42: CO | G42: 3 | H42: =IF('CO 3'!Z16>0,'CO 3'!Z16,"") | M42: =IF('CO 3'!Z16<0,'CO 3'!Z16,"") | S42: ='CO 3'!W16 -> 0
F43: CO | G43: 4 | H43: =IF('CO 4'!Z16>0,'CO 4'!Z16,"") | M43: =IF('CO 4'!Z16<0,'CO 4'!Z16,"") | S43: ='CO 4'!W16 -> 0
F44: CO | G44: 5 | H44: =IF('CO 5'!Z16>0,'CO 5'!Z16,"") | M44: =IF('CO 5'!Z16<0,'CO 5'!Z16,"") | S44: ='CO 5'!W16 -> 0
...

Sheet CO 8
Q1: CHANGE ORDER (CO)
A2: Project Name: | F2: ='CO 1'!F2:AB2 -> FTW-336A | W2: DU Job #: | Z2: ='CO 1'!Z2:AA2 -> J101395 | AB2: CO #
A3: Contractor: | F3: ='CO 1'!F3:AB3 -> TAR/TBI Construction | W3: DU PO #: | Z3: ='CO 1'!Z3:AA3 -> n/a | AB3: 8
B4: The Contractor shall furnish all labor, equipment and materials, and perform all work necessary to complete the work described herein and/or in the document(s) attached hereto. DO NOT start work under this CO until you receive a fully executed original (signed by Doyon Utilities), or a written Notice to Proceed.
B5: Description of Work: | V5: Time Change* | Z5: Price Change | AE5: Time | AF5: Time
B6: Reference | F6: Item Description | V6: Cal. Days** | Z6: U.S. Dollars** | AE6: Reductions | AF6: Increases
AE7: =IF(W7<0,W7,0) -> 0 | AF7: =IF(W7>0,W7,0) -> 0
AE8: =IF(W8<0,W8,0) -> 0 | AF8: =IF(W8>0,W8,0) -> 0
AE9: =IF(W9<0,W9,0) -> 0 | AF9: =IF(W9>0,W9,0) -> 0
AE10: =IF(W10<0,W10,0) -> 0 | AF10: =IF(W10>0,W10,0) -> 0
AE11: =IF(W11<0,W11,0) -> 0 | AF11: =IF(W11>0,W11,0) -> 0
AE12: =IF(W12<0,W12,0) -> 0 | AF12: =IF(W12>0,W12,0) -> 0
AE13: =IF(W13<0,W13,0) -> 0 | AF13: =IF(W13>0,W13,0) -> 0
AE14: =IF(W14<0,W14,0) -> 0 | AF14: =IF(W14>0,W14,0) -> 0
AE15: =IF(W15<0,W15,0) -> 0 | AF15: =IF(W15>0,W15,0) -> 0
B16: * Time Changes are NOT cumulative; Net Time Change = largest increase + largest decrease. ** Value in parenthesis is negative; i.e., (time reduction) or ($ credit) | S16: Net Change: | W16: =MIN(AE7:AE15)+MAX(AF7:AF15) -> 0 | Z16: =SUM(Z7:AB15) -> 0
B17: As a result of this Change Order: | K17: the Contract Completion Time is | S17: =IF(W16=0,"UNCHANGED,",IF(W16<0,"REDUCED","INCREASED")) -> UNCHANGED, | W17: =IF(W16=0,"",W16) | Y17: =IF(W16=0,"","Calendar Day(s),")
B18: and the Total Contract Price is | S18: =IF(Z16=0,"UNCHANGED.",IF(Z16<0,"REDUCED","INCREASED")) -> UNCHANGED. | W18: =IF(Z16=0,"",Z16) | AA18: =IF(Z16<>0,".","")
B19: The Total Adjusted Contract Price to date and the Adjusted Contract Completion Date are stated in the Contract Summary below.
B20: The Contractor hereby accepts the foregoing adjustment as a final and complete equitable adjustment in full accord and satisfaction of all past, present and future liability originating under any Article in the Contract by reason of the facts and circumstances giving rise to this Change Order. Except as hereby modified, all terms and conditions of said Contract, as heretofore modified, remain unchanged and in full force and effect.
C21: THIS CHANGE ORDER IS HEREBY ACCEPTED: | P21: RECOMMENDED BY:
C22: Contractor:
C24: =F3 -> TAR/TBI Construction | P24: Architect/Engineer | Z24: Date
C26: /
P27: Doyon Utilities Project Manager | Z27: Date
C28: Typed or Printed Name / Title | P28: ACCEPTED BY:
C30: Signature | K30: Date | P30: for Doyon Utilities | Z30: Date
B31: CONTRACT SUMMARY UPON EXECUTION OF THIS CHANGE ORDER:
B32: Previous Contract Completion Date: | K32: ='CO 7'!Y32 | O32: Adjusted Contract Completion Date: | Y32: =IF(K32>0,K32+W16,"")
B33: Original Contract Amount: | K33: ='CO 1'!K33:N33 -> 746512 | O33: Previous Contract Total: | Y33: =SUM(F33:K35) -> 756905
B34: Previous Additions: | K34: =H39 -> 10393 | O34: =IF(Z16=0,"This Change Order:",IF(Z16<0,"This Change Order, DEDUCT:","This Change Order, ADD:")) -> This Change Order: | Y34: =Z16 -> 0
B35: Previous Deductions: | K35: =M39 -> 0 | O35: Total Adjusted Contract Price to date: | Y35: =SUM(Y33:Y34) -> 756905
F37: Summary of Previous Change Orders
H38: Price Additions | M38: Price Deductions | Q38: Net Time Change (Days)
F39: Totals: | H39: =SUM(H40:H46) -> 10393 | M39: =SUM(M40:M46) -> 0 | S39: =SUM(S40:S46) -> 0
F40: CO | G40: 1 | H40: =IF('CO 1'!Z16>0,'CO 1'!Z16,"") -> 10393 | M40: =IF('CO 1'!Z16<0,'CO 1'!Z16,"") | S40: ='CO 1'!W16 -> 0
F41: CO | G41: 2 | H41: =IF('CO 2'!Z16>0,'CO 2'!Z16,"") | M41: =IF('CO 2'!Z16<0,'CO 2'!Z16,"") | S41: ='CO 2'!W16 -> 0
F42: CO | G42: 3 | H42: =IF('CO 3'!Z16>0,'CO 3'!Z16,"") | M42: =IF('CO 3'!Z16<0,'CO 3'!Z16,"") | S42: ='CO 3'!W16 -> 0
F43: CO | G43: 4 | H43: =IF('CO 4'!Z16>0,'CO 4'!Z16,"") | M43: =IF('CO 4'!Z16<0,'CO 4'!Z16,"") | S43: ='CO 4'!W16 -> 0
F44: CO | G44: 5 | H44: =IF('CO 5'!Z16>0,'CO 5'!Z16,"") | M44: =IF('CO 5'!Z16<0,'CO 5'!Z16,"") | S44: ='CO 5'!W16 -> 0
...

Sheet CO 9
Q1: CHANGE ORDER (CO)
A2: Project Name: | F2: ='CO 1'!F2:AB2 -> FTW-336A | W2: DU Job #: | Z2: ='CO 1'!Z2:AA2 -> J101395 | AB2: CO #
A3: Contractor: | F3: ='CO 1'!F3:AB3 -> TAR/TBI Construction | W3: DU PO #: | Z3: ='CO 1'!Z3:AA3 -> n/a | AB3: 9
B4: The Contractor shall furnish all labor, equipment and materials, and perform all work necessary to complete the work described herein and/or in the document(s) attached hereto. DO NOT start work under this CO until you receive a fully executed original (signed by Doyon Utilities), or a written Notice to Proceed.
B5: Description of Work: | V5: Time Change* | Z5: Price Change | AE5: Time | AF5: Time
B6: Reference | F6: Item Description | V6: Cal. Days** | Z6: U.S. Dollars** | AE6: Reductions | AF6: Increases
AE7: =IF(W7<0,W7,0) -> 0 | AF7: =IF(W7>0,W7,0) -> 0
AE8: =IF(W8<0,W8,0) -> 0 | AF8: =IF(W8>0,W8,0) -> 0
AE9: =IF(W9<0,W9,0) -> 0 | AF9: =IF(W9>0,W9,0) -> 0
AE10: =IF(W10<0,W10,0) -> 0 | AF10: =IF(W10>0,W10,0) -> 0
AE11: =IF(W11<0,W11,0) -> 0 | AF11: =IF(W11>0,W11,0) -> 0
AE12: =IF(W12<0,W12,0) -> 0 | AF12: =IF(W12>0,W12,0) -> 0
AE13: =IF(W13<0,W13,0) -> 0 | AF13: =IF(W13>0,W13,0) -> 0
AE14: =IF(W14<0,W14,0) -> 0 | AF14: =IF(W14>0,W14,0) -> 0
AE15: =IF(W15<0,W15,0) -> 0 | AF15: =IF(W15>0,W15,0) -> 0
B16: * Time Changes are NOT cumulative; Net Time Change = largest increase + largest decrease. ** Value in parenthesis is negative; i.e., (time reduction) or ($ credit) | S16: Net Change: | W16: =MIN(AE7:AE15)+MAX(AF7:AF15) -> 0 | Z16: =SUM(Z7:AB15) -> 0
B17: As a result of this Change Order: | K17: the Contract Completion Time is | S17: =IF(W16=0,"UNCHANGED,",IF(W16<0,"REDUCED","INCREASED")) -> UNCHANGED, | W17: =IF(W16=0,"",W16) | Y17: =IF(W16=0,"","Calendar Day(s),")
B18: and the Total Contract Price is | S18: =IF(Z16=0,"UNCHANGED.",IF(Z16<0,"REDUCED","INCREASED")) -> UNCHANGED. | W18: =IF(Z16=0,"",Z16) | AA18: =IF(Z16<>0,".","")
B19: The Total Adjusted Contract Price to date and the Adjusted Contract Completion Date are stated in the Contract Summary below.
B20: The Contractor hereby accepts the foregoing adjustment as a final and complete equitable adjustment in full accord and satisfaction of all past, present and future liability originating under any Article in the Contract by reason of the facts and circumstances giving rise to this Change Order. Except as hereby modified, all terms and conditions of said Contract, as heretofore modified, remain unchanged and in full force and effect.
C21: THIS CHANGE ORDER IS HEREBY ACCEPTED: | P21: RECOMMENDED BY:
C22: Contractor:
C24: =F3 -> TAR/TBI Construction | P24: Architect/Engineer | Z24: Date
C26: /
P27: Doyon Utilities Project Manager | Z27: Date
C28: Typed or Printed Name / Title | P28: ACCEPTED BY:
C30: Signature | K30: Date | P30: for Doyon Utilities | Z30: Date
B31: CONTRACT SUMMARY UPON EXECUTION OF THIS CHANGE ORDER:
B32: Previous Contract Completion Date: | K32: ='CO 8'!Y32 | O32: Adjusted Contract Completion Date: | Y32: =IF(K32>0,K32+W16,"")
B33: Original Contract Amount: | K33: ='CO 1'!K33:N33 -> 746512 | O33: Previous Contract Total: | Y33: =SUM(F33:K35) -> 756905
B34: Previous Additions: | K34: =H39 -> 10393 | O34: =IF(Z16=0,"This Change Order:",IF(Z16<0,"This Change Order, DEDUCT:","This Change Order, ADD:")) -> This Change Order: | Y34: =Z16 -> 0
B35: Previous Deductions: | K35: =M39 -> 0 | O35: Total Adjusted Contract Price to date: | Y35: =SUM(Y33:Y34) -> 756905
F37: Summary of Previous Change Orders
H38: Price Additions | M38: Price Deductions | Q38: Net Time Change (Days)
F39: Totals: | H39: =SUM(H40:H47) -> 10393 | M39: =SUM(M40:M47) -> 0 | S39: =SUM(S40:S47) -> 0
F40: CO | G40: 1 | H40: =IF('CO 1'!Z16>0,'CO 1'!Z16,"") -> 10393 | M40: =IF('CO 1'!Z16<0,'CO 1'!Z16,"") | S40: ='CO 1'!W16 -> 0
F41: CO | G41: 2 | H41: =IF('CO 2'!Z16>0,'CO 2'!Z16,"") | M41: =IF('CO 2'!Z16<0,'CO 2'!Z16,"") | S41: ='CO 2'!W16 -> 0
F42: CO | G42: 3 | H42: =IF('CO 3'!Z16>0,'CO 3'!Z16,"") | M42: =IF('CO 3'!Z16<0,'CO 3'!Z16,"") | S42: ='CO 3'!W16 -> 0
F43: CO | G43: 4 | H43: =IF('CO 4'!Z16>0,'CO 4'!Z16,"") | M43: =IF('CO 4'!Z16<0,'CO 4'!Z16,"") | S43: ='CO 4'!W16 -> 0
F44: CO | G44: 5 | H44: =IF('CO 5'!Z16>0,'CO 5'!Z16,"") | M44: =IF('CO 5'!Z16<0,'CO 5'!Z16,"") | S44: ='CO 5'!W16 -> 0
...

Sheet CO 10
Q1: CHANGE ORDER (CO)
A2: Project Name: | F2: ='CO 1'!F2:AB2 -> FTW-336A | W2: DU Job #: | Z2: ='CO 1'!Z2:AA2 -> J101395 | AB2: CO #
A3: Contractor: | F3: ='CO 1'!F3:AB3 -> TAR/TBI Construction | W3: DU PO #: | Z3: ='CO 1'!Z3:AA3 -> n/a | AB3: 10
B4: The Contractor shall furnish all labor, equipment and materials, and perform all work necessary to complete the work described herein and/or in the document(s) attached hereto. DO NOT start work under this CO until you receive a fully executed original (signed by Doyon Utilities), or a written Notice to Proceed.
B5: Description of Work: | V5: Time Change* | Z5: Price Change | AE5: Time | AF5: Time
B6: Reference | F6: Item Description | V6: Cal. Days** | Z6: U.S. Dollars** | AE6: Reductions | AF6: Increases
AE7: =IF(W7<0,W7,0) -> 0 | AF7: =IF(W7>0,W7,0) -> 0
AE8: =IF(W8<0,W8,0) -> 0 | AF8: =IF(W8>0,W8,0) -> 0
AE9: =IF(W9<0,W9,0) -> 0 | AF9: =IF(W9>0,W9,0) -> 0
AE10: =IF(W10<0,W10,0) -> 0 | AF10: =IF(W10>0,W10,0) -> 0
AE11: =IF(W11<0,W11,0) -> 0 | AF11: =IF(W11>0,W11,0) -> 0
AE12: =IF(W12<0,W12,0) -> 0 | AF12: =IF(W12>0,W12,0) -> 0
AE13: =IF(W13<0,W13,0) -> 0 | AF13: =IF(W13>0,W13,0) -> 0
AE14: =IF(W14<0,W14,0) -> 0 | AF14: =IF(W14>0,W14,0) -> 0
AE15: =IF(W15<0,W15,0) -> 0 | AF15: =IF(W15>0,W15,0) -> 0
B16: * Time Changes are NOT cumulative; Net Time Change = largest increase + largest decrease. ** Value in parenthesis is negative; i.e., (time reduction) or ($ credit) | S16: Net Change: | W16: =MIN(AE7:AE15)+MAX(AF7:AF15) -> 0 | Z16: =SUM(Z7:AB15) -> 0
B17: As a result of this Change Order: | K17: the Contract Completion Time is | S17: =IF(W16=0,"UNCHANGED,",IF(W16<0,"REDUCED","INCREASED")) -> UNCHANGED, | W17: =IF(W16=0,"",W16) | Y17: =IF(W16=0,"","Calendar Day(s),")
B18: and the Total Contract Price is | S18: =IF(Z16=0,"UNCHANGED.",IF(Z16<0,"REDUCED","INCREASED")) -> UNCHANGED. | W18: =IF(Z16=0,"",Z16) | AA18: =IF(Z16<>0,".","")
B19: The Total Adjusted Contract Price to date and the Adjusted Contract Completion Date are stated in the Contract Summary below.
B20: The Contractor hereby accepts the foregoing adjustment as a final and complete equitable adjustment in full accord and satisfaction of all past, present and future liability originating under any Article in the Contract by reason of the facts and circumstances giving rise to this Change Order. Except as hereby modified, all terms and conditions of said Contract, as heretofore modified, remain unchanged and in full force and effect.
C21: THIS CHANGE ORDER IS HEREBY ACCEPTED: | P21: RECOMMENDED BY:
C22: Contractor:
C24: =F3 -> TAR/TBI Construction | P24: Architect/Engineer | Z24: Date
C26: /
P27: Doyon Utilities Project Manager | Z27: Date
C28: Typed or Printed Name / Title | P28: ACCEPTED BY:
C30: Signature | K30: Date | P30: for Doyon Utilities | Z30: Date
B31: CONTRACT SUMMARY UPON EXECUTION OF THIS CHANGE ORDER:
B32: Previous Contract Completion Date: | K32: ='CO 9'!Y32 | O32: Adjusted Contract Completion Date: | Y32: =IF(K32>0,K32+W16,"")
B33: Original Contract Amount: | K33: ='CO 1'!K33:N33 -> 746512 | O33: Previous Contract Total: | Y33: =SUM(F33:K35) -> 756905
B34: Previous Additions: | K34: =H39 -> 10393 | O34: =IF(Z16=0,"This Change Order:",IF(Z16<0,"This Change Order, DEDUCT:","This Change Order, ADD:")) -> This Change Order: | Y34: =Z16 -> 0
B35: Previous Deductions: | K35: =M39 -> 0 | O35: Total Adjusted Contract Price to date: | Y35: =SUM(Y33:Y34) -> 756905
F37: Summary of Previous Change Orders
H38: Price Additions | M38: Price Deductions | Q38: Net Time Change (Days)
F39: Totals: | H39: =SUM(H40:H48) -> 10393 | M39: =SUM(M40:M48) -> 0 | S39: =SUM(S40:S48) -> 0
F40: CO | G40: 1 | H40: =IF('CO 1'!Z16>0,'CO 1'!Z16,"") -> 10393 | M40: =IF('CO 1'!Z16<0,'CO 1'!Z16,"") | S40: ='CO 1'!W16 -> 0
F41: CO | G41: 2 | H41: =IF('CO 2'!Z16>0,'CO 2'!Z16,"") | M41: =IF('CO 2'!Z16<0,'CO 2'!Z16,"") | S41: ='CO 2'!W16 -> 0
F42: CO | G42: 3 | H42: =IF('CO 3'!Z16>0,'CO 3'!Z16,"") | M42: =IF('CO 3'!Z16<0,'CO 3'!Z16,"") | S42: ='CO 3'!W16 -> 0
F43: CO | G43: 4 | H43: =IF('CO 4'!Z16>0,'CO 4'!Z16,"") | M43: =IF('CO 4'!Z16<0,'CO 4'!Z16,"") | S43: ='CO 4'!W16 -> 0
F44: CO | G44: 5 | H44: =IF('CO 5'!Z16>0,'CO 5'!Z16,"") | M44: =IF('CO 5'!Z16<0,'CO 5'!Z16,"") | S44: ='CO 5'!W16 -> 0
...

Sheet DCVR007
M4: Back to CO 1
M8: Go to Proposal

Sheet DCVR007_Proposal
N5: Back to DCVR007
