Workbook
Name CapitalFormula: '[1]Capital Reports'!$E$15:$BC$17
Name DOT: #REF!
Name FromYear: [1]MainSheet!$B$14
Name GrandTotals: '[1]Capital Reports'!$E$75:$BC$77
Name HeaderRow: [1]MainSheet!$B$1
Name Inf: #REF!
Name Inflation: [2]InflationSheet!$O$2:$BL$2
Name InflationFactor: [1]MainSheet!$B$13
Name INPUT: #REF!
Name Item: #REF!
Name ItemColumn: [1]MainSheet!$B$2
Name Linear_Asset: #REF!
Name LinearAssetColumn: [1]MainSheet!$B$6
Name Major_Maint_Duration__Years: #REF!
Name Major_Maint_Total_Expense: #REF!
Name Major_Maint_Year: #REF!
Name MajorMaintCostColumn: [1]MainSheet!$B$11
Name MajorMaintDurationColumn: [1]MainSheet!$B$12
Name MajorMaintYearColumn: [1]MainSheet!$B$10
Name NameTable: [1]MainSheet!$A$1:$B$15
Name Original_Cost: #REF!
Name Original_Installation_Year: #REF!
Name Original_Life: #REF!
Name OriginalCostColumn: [1]MainSheet!$B$4
Name OriginalLifeColumn: [1]MainSheet!$B$5
Name OriginalYearInstalledColumn: [1]MainSheet!$B$3
Name Replace_Cost: #REF!
Name Replace_Life: #REF!
Name Replace_Year: #REF!
Name ReplaceCostColumn: [1]MainSheet!$B$8
Name ReplaceLifeColumn: [1]MainSheet!$B$9
Name ReplaceYearColumn: [1]MainSheet!$B$7
Name Source_Book: #REF!
Name Source_Row: #REF!
Name Source_Sheet: #REF!
Name Title: #REF!
Name Total: #REF!
Name ToYear: [1]MainSheet!$B$15
Name Version: [1]MainSheet!$B$16
Name Years: #REF!

Sheet Instructions
B2: Capital Job Initiation (JI)
A3: Introduction
B4: The Job Initiation Form is a working document for managing and directing a capital project. It is the focal point at which information relating to the project is gathered for approval by Management and serves to remind all of the project scope. A clear understanding of the project ensures that the major needs are identified and incorporated into the planning of the project.
B5: The primary use of the document is to act as a base document against which approval to advance can be given, progress can be assessed, and changes can be made as needed.
B6: Parts of the JI Form might need to be amended as the project progresses.
A8: Process Flow
B9: Complete JI Form tab
B10: Complete Cash Flow tab
B11: Submit JI Form and Cash Flow to DU President/CEO (George Gordon) for approval
B12: Acquisition or construction of new facilities shall be done in accordance with the Army and Management Committee’s approved capital plan, or modifications to the contracts. Prior to approving the acquisition or construction of a new asset, management shall be presented with an estimate of the full cost to purchase or construct the new asset. Upon determination of approval, management and/or the Management Committee will ensure resources are adequate to meet these needs.
B13: Upon approval, signed documents should be forwarded to Accounting at USA.
B14: Job #s will be created in NAV Job System and provided via email to requesting party.
B15: Copies of all signed contracts are provided to Accounting and filed in the job file (which will be incorporated into the CPR (Continuing Property Record)).
B16: A copy of all project plans and specifications are provided to accounting and kept in the job file.
B18: All change orders require approval by management.
B19: Updates/changes are provided to Accounting regularly.
B20: Notify Accounting when the project is scheduled to be completed and placed into service.
A22: JI Form - Help
B23: General Definitions
B25: JI Form - Job Initiation Form
B27: Capital Projects - Defined as investor owned or contributed plant (self constructed or subcontracted by bid award). Job tasks are defined to ensure proper classification upon completion of the project.
B29: General Help
B31: JI Form - The Job Initiation Form is integrated with links to help the end-user complete the form. Tips can be found within the JI Form by hovering the mouse pointer on the name of a field. Further information can be found by clicking directly on the name of a field.
B33: Only enter data into the highlighted cells and the drop-down selection cells. Highlighting will automatically disappear from each cell as data is entered into the cell. If all else fails, fill the form out by hand (the drop down values for each field are listed in the help description for each field), or seek assistance from Accounting.
B36: Help - JI Form - Field Assistance
B38: Job # This field will be completed by Accounting | C38: return to field
B40: Job Description (Short) This field will carry forward as the name or title of the job. Be as specific as you can, within space provided. Maximum of 50 characters. | C40: return to field
B42: Job Description (Long) Explain what the project is setting out to achieve. Be as specific as you can. Target: One paragraph. | C42: return to field
B44: Division Using the drop down menu, select the applicable Division (Corporate, Fort Wainwright, Fort Richardson or Fort Greely). Only one selection is permitted per JI Form. | C44: return to field
B46: Utility Using the drop down menu, select the applicable Utility (Corporate, Natural Gas, Water, Waste Water, Electric Distribution, Central Heating Plant). Only one selection is permitted per JI Form. | C46: return to field
B48: Requested by Using the drop down menu, select the applicable option (1. Original Contract, 2. Contract Mod, 3. COR MOD, 4. Other MOD, 5. Corporate, 6. An Individual). Only one selection is permitted per JI Form. Data in this field should correspond with those in the field titled, "Requested By Description". | C48: return to field
B50: Requested by Description Based on the selection in the "Requested By" field, enter the corresponding information: select the applicable option | C50: return to field
B51: 1. Original Contract - Enter Letter/# designator (i.e. HCU10)
B52: 2. Contract Mod - Enter Letter/# designator (i.e. HCU10)
B53: 3. COR MOD (Contracting Officer's Rep MOD) - Enter Letter/# designator
B54: 4. Other MOD - Enter Letter/# designator
B55: 5. Corporate - Enter Corporate Department or Title (i.e. IT, etc.)
B56: 6. An Individual - This should be the last choice! Enter the name of person
B57: Data in this field should correspond with those in the field titled, "Requested By".
B59: Project Manager Enter the name of the Project Manager/Requestor for this job. | C59: return to field
...

Sheet Job Initiation Form
B5: Job #:____________
B6: Capital Job Initiation form
B7: Request for creation of new Job number
A8: Today's Date: | B8: 40040
A10: Job Description (Short): | B10: New HDS Utility Service for FTW 336A- Aircraft Parts Storage
A12: Job Description (Long): | B12: Fort Wainwright requires new service connections to provide utility service to the facility being constructed under U.S. Army Corps of Engineers (USACE) Project FTW 336A – Aircraft Parts Storage. Doyon Utilities, LLC (DU) shall be responsible for design of all service connections up to the applicable points of demarcation. This Request for Proposal is for design effort only. As part of the design process, DU will be expected to attend design coordination meetings and design review meetings.
B13: .
A14: Division: | B14: 5 | D14: Utility: | E14: 2
A16: Requested by: | D16: Project Manager: | E16: Norman Sather
A17: Requested by Description: | B17: RFP № FWA-09-021
A19: Start Date: | B19: 40056 | D19: Est Completion Date: | E19: 40117
A21: Subclass: | D21: Subclass Cost Estimate | E21: 50000
E22: 50000
D26: Total Subclass Estimate | E26: =SUM(E21:E25) -> 100000
A27: Cost Estimate: | B27: 100000 | D27: Cost Est - Subclass Est | E27: 100000
A29: Cash Flow Estimate:
A30: Description of retirements: | C30: None
A32: Additional comments: | C32: Engineering Design Only
A34: Your name: | B34: Norman Sather
A36: THIS FORM IS NOT VALID WITHOUT APPROVING SIGNATURE OF DAN GAVORA, PRESIDENT/CEO
A37: For use by DU President/CEO: | D37: For use by Accounting Office:
A38: Approved by: | D38: Assigned Job #:
A39: Approved on: | D39: Date Job Created:

Sheet CashFlow
A1: Cash Flow
A2: Job Description: | C2: =LEFT('Job Initiation Form'!B10,50) -> New HDS Utility Service for FTW 336A- Aircraft Par
A3: Job #: | C3: ='Job Initiation Form'!E38 -> 0
A4: DIV: | B4: =VLOOKUP('Job Initiation Form'!B14,'form picklists'!O3:P7,2) -> Fort Wainwright
A5: Utility: | B5: =VLOOKUP('Job Initiation Form'!E14,'form picklists'!Q3:R9,2) -> Central Heating Plant
A6: CPM?:
A7: Start Month: | B7: ='Job Initiation Form'!B19 -> 40056
A8: Duration (months): | B8: =DAYS360('Job Initiation Form'!B19,'Job Initiation Form'!E19,FALSE)/30 -> 2
B10: =YEAR(B7) -> 2009 | C10: =IF(B12=12,$B$10+1," ") | D10: =IF(C12=12,$B$10+1," ") | E10: =IF(D12=12,$B$10+1,IF(D12="Q4",A10+1," ")) | F10: =IF(E12=12,$B$10+1,IF(E12="Q4",B10+1," ")) | G10: =IF(F12=12,$B$10+1,IF(F12="Q4",C10+1," ")) -> 2010 | H10: =IF(G12=12,$B$10+1,IF(G12="Q4",D10+1," ")) | I10: =IF(H12=12,$B$10+1,IF(H12="Q4",E10+1," ")) | J10: =IF(I12=12,$B$10+1,IF(I12="Q4",F10+1," ")) | K10: =IF(J12=12,$B$10+1,IF(J12="Q4",G10+1," ")) -> 2011 | L10: =IF(K12=12,$B$10+1,IF(K12="Q4",H10+1," ")) | M10: =IF(L12=12,$B$10+1,IF(L12="Q4",I10+1," "))
B11: =LOOKUP(B$12,{0,1,2,3,4,5,6,7,8,9,10,11,12,13,"Q1","Q2","Q3","Q4"},{" ","Q1"," "," ","Q2"," "," ","Q3"," "," ","Q4"," "," ","Q1","Q1","Q2","Q3","Q4"}) | C11: =LOOKUP(C$12,{0,1,2,3,4,5,6,7,8,9,10,11,12,13,"Q1","Q2","Q3","Q4"},{" ","Q1"," "," ","Q2"," "," ","Q3"," "," ","Q4"," "," ","Q1","Q1","Q2","Q3","Q4"}) | D11: =LOOKUP(D$12,{0,1,2,3,4,5,6,7,8,9,10,11,12,13,"Q1","Q2","Q3","Q4"},{" ","Q1"," "," ","Q2"," "," ","Q3"," "," ","Q4"," "," ","Q1","Q1","Q2","Q3","Q4"}) -> Q4 | E11: =LOOKUP(E$12,{0,1,2,3,4,5,6,7,8,9,10,11,12,13,"Q1","Q2","Q3","Q4"},{" ","Q1"," "," ","Q2"," "," ","Q3"," "," ","Q4"," "," ","Q1","Q1","Q2","Q3","Q4"}) | F11: =LOOKUP(F$12,{0,1,2,3,4,5,6,7,8,9,10,11,12,13,"Q1","Q2","Q3","Q4"},{" ","Q1"," "," ","Q2"," "," ","Q3"," "," ","Q4"," "," ","Q1","Q1","Q2","Q3","Q4"}) | G11: =LOOKUP(G$12,{0,1,2,3,4,5,6,7,8,9,10,11,12,13,"Q1","Q2","Q3","Q4"},{" ","Q1"," "," ","Q2"," "," ","Q3"," "," ","Q4"," "," ","Q1","Q1","Q2","Q3","Q4"}) -> Q1 | H11: =LOOKUP(H$12,{0,1,2,3,4,5,6,7,8,9,10,11,12,13,"Q1","Q2","Q3","Q4"},{" ","Q1"," "," ","Q2"," "," ","Q3"," "," ","Q4"," "," ","Q1","Q1","Q2","Q3","Q4"}) -> Q2 | I11: =LOOKUP(I$12,{0,1,2,3,4,5,6,7,8,9,10,11,12,13,"Q1","Q2","Q3","Q4"},{" ","Q1"," "," ","Q2"," "," ","Q3"," "," ","Q4"," "," ","Q1","Q1","Q2","Q3","Q4"}) -> Q3 | ... M11: =LOOKUP(M$12,{0,1,2,3,4,5,6,7,8,9,10,11,12,13,"Q1","Q2","Q3","Q4"},{" ","Q1"," "," ","Q2"," "," ","Q3"," "," ","Q4"," "," ","Q1","Q1","Q2","Q3","Q4"}) -> Q3 | N11: Estimate
B12: =MONTH(B7) -> 8 | C12: =LOOKUP(B$12,{0,1,2,3,4,5,6,7,8,9,10,11,12,"Q1","Q2","Q3","Q4"},{"ERROR",2,3,4,5,6,7,8,9,10,11,12,"Q1","Q2","Q3","Q4","Q1"}) -> 9 | D12: =LOOKUP(C$12,{0,1,2,3,4,5,6,7,8,9,10,11,12,"Q1","Q2","Q3","Q4"},{"ERROR",2,3,4,5,6,7,8,9,10,11,12,"Q1","Q2","Q3","Q4","Q1"}) -> 10 | E12: =LOOKUP(D$12,{0,1,2,3,4,5,6,7,8,9,10,11,12,"Q1","Q2","Q3","Q4"},{"ERROR",2,3,4,5,6,7,8,9,10,11,12,"Q1","Q2","Q3","Q4","Q1"}) -> 11 | F12: =LOOKUP(E$12,{0,1,2,3,4,5,6,7,8,9,10,11,12,"Q1","Q2","Q3","Q4"},{"ERROR",2,3,4,5,6,7,8,9,10,11,12,"Q1","Q2","Q3","Q4","Q1"}) -> 12 | G12: =LOOKUP(F$12,{0,1,2,3,4,5,6,7,8,9,10,11,12,"Q1","Q2","Q3","Q4"},{"ERROR",2,3,4,5,6,7,8,9,10,11,12,"Q1","Q2","Q3","Q4","Q1"}) -> Q1 | H12: =LOOKUP(G$12,{0,1,2,3,4,5,6,7,8,9,10,11,12,"Q1","Q2","Q3","Q4"},{"ERROR",2,3,4,5,6,7,8,9,10,11,12,"Q1","Q2","Q3","Q4","Q1"}) -> Q2 | I12: =LOOKUP(H$12,{0,1,2,3,4,5,6,7,8,9,10,11,12,"Q1","Q2","Q3","Q4"},{"ERROR",2,3,4,5,6,7,8,9,10,11,12,"Q1","Q2","Q3","Q4","Q1"}) -> Q3 | J12: =LOOKUP(I$12,{0,1,2,3,4,5,6,7,8,9,10,11,12,"Q1","Q2","Q3","Q4"},{"ERROR",2,3,4,5,6,7,8,9,10,11,12,"Q1","Q2","Q3","Q4","Q1"}) -> Q4 | ... M12: =LOOKUP(L$12,{0,1,2,3,4,5,6,7,8,9,10,11,12,"Q1","Q2","Q3","Q4"},{"ERROR",2,3,4,5,6,7,8,9,10,11,12,"Q1","Q2","Q3","Q4","Q1"}) -> Q3
B14: 0 | E14: 0 | F14: 0 | G14: 99232.258 | H14: 99232.258 | I14: 99232.258 | J14: 99232.258 | K14: 0 | L14: 0 | M14: 0 | N14: =SUM(B14:M14) -> 396929.03
B17: =SUM(B13:B16) -> 0 | C17: =SUM(C13:C16) -> 0 | D17: =SUM(D13:D16) -> 0 | E17: =SUM(E13:E16) -> 0 | F17: =SUM(F13:F16) -> 0 | G17: =SUM(G13:G16) -> 99232.258 | H17: =SUM(H13:H16) -> 99232.258 | I17: =SUM(I13:I16) -> 99232.258 | ... N17: =SUM(N13:N16) -> 396929.03
D19: =D17+C17+B17 -> 0 | E19: =E17+D17+C17+B17 -> 0 | F19: =F17+E19 -> 0 | G19: =G17+F19 -> 99232.258 | H19: =H17+G19 -> 198464.52 | I19: =I17+H19 -> 297696.77 | J19: =J17+I19 -> 396929.03 | K19: =K17+J19 -> 396929.03 | L19: =L17+K19 -> 396929.03 | M19: =M17+L19 -> 396929.03
B22: =IF(M12=12,$B$10+1,IF(M12="Q4",J10+1," ")) | C22: =IF(B23=12,$B$10+1,IF(B23="Q4",K10+1," ")) -> 2012 | D22: =IF(C23=12,$B$10+1,IF(C23="Q4",L10+1," ")) | E22: =IF(D23=12,$B$10+1,IF(D23="Q4",M10+1," ")) | F22: =IF(E23=12,$B$10+1,IF(E23="Q4",B22+1," ")) | G22: =IF(F23=12,$B$10+1,IF(F23="Q4",C22+1," ")) -> 2013 | H22: =IF(G23=12,$B$10+1,IF(G23="Q4",D22+1," ")) | I22: =IF(H23=12,$B$10+1,IF(H23="Q4",E22+1," ")) | J22: =IF(I23=12,$B$10+1,IF(I23="Q4",F22+1," ")) | K22: =IF(J23=12,$B$10+1,IF(J23="Q4",G22+1," ")) -> 2014 | L22: =IF(K23=12,$B$10+1,IF(K23="Q4",H22+1," ")) | M22: =IF(L23=12,$B$10+1,IF(L23="Q4",I22+1," ")) | N22: Total Estimate
B23: =LOOKUP(B$24,{0,1,2,3,4,5,6,7,8,9,10,11,12,13,"Q1","Q2","Q3","Q4"},{" ","Q1"," "," ","Q2"," "," ","Q3"," "," ","Q4"," "," ","Q1","Q1","Q2","Q3","Q4"}) -> Q4 | C23: =LOOKUP(C$24,{0,1,2,3,4,5,6,7,8,9,10,11,12,13,"Q1","Q2","Q3","Q4"},{" ","Q1"," "," ","Q2"," "," ","Q3"," "," ","Q4"," "," ","Q1","Q1","Q2","Q3","Q4"}) -> Q1 | D23: =LOOKUP(D$24,{0,1,2,3,4,5,6,7,8,9,10,11,12,13,"Q1","Q2","Q3","Q4"},{" ","Q1"," "," ","Q2"," "," ","Q3"," "," ","Q4"," "," ","Q1","Q1","Q2","Q3","Q4"}) -> Q2 | E23: =LOOKUP(E$24,{0,1,2,3,4,5,6,7,8,9,10,11,12,13,"Q1","Q2","Q3","Q4"},{" ","Q1"," "," ","Q2"," "," ","Q3"," "," ","Q4"," "," ","Q1","Q1","Q2","Q3","Q4"}) -> Q3 | F23: =LOOKUP(F$24,{0,1,2,3,4,5,6,7,8,9,10,11,12,13,"Q1","Q2","Q3","Q4"},{" ","Q1"," "," ","Q2"," "," ","Q3"," "," ","Q4"," "," ","Q1","Q1","Q2","Q3","Q4"}) -> Q4 | G23: =LOOKUP(G$24,{0,1,2,3,4,5,6,7,8,9,10,11,12,13,"Q1","Q2","Q3","Q4"},{" ","Q1"," "," ","Q2"," "," ","Q3"," "," ","Q4"," "," ","Q1","Q1","Q2","Q3","Q4"}) -> Q1 | H23: =LOOKUP(H$24,{0,1,2,3,4,5,6,7,8,9,10,11,12,13,"Q1","Q2","Q3","Q4"},{" ","Q1"," "," ","Q2"," "," ","Q3"," "," ","Q4"," "," ","Q1","Q1","Q2","Q3","Q4"}) -> Q2 | I23: =LOOKUP(I$24,{0,1,2,3,4,5,6,7,8,9,10,11,12,13,"Q1","Q2","Q3","Q4"},{" ","Q1"," "," ","Q2"," "," ","Q3"," "," ","Q4"," "," ","Q1","Q1","Q2","Q3","Q4"}) -> Q3 | ... M23: =LOOKUP(M$24,{0,1,2,3,4,5,6,7,8,9,10,11,12,13,"Q1","Q2","Q3","Q4"},{" ","Q1"," "," ","Q2"," "," ","Q3"," "," ","Q4"," "," ","Q1","Q1","Q2","Q3","Q4"}) -> Q3
B24: =LOOKUP(M$12,{0,1,2,3,4,5,6,7,8,9,10,11,12,"Q1","Q2","Q3","Q4"},{"ERROR",2,3,4,5,6,7,8,9,10,11,12,"Q1","Q2","Q3","Q4","Q1"}) -> Q4 | C24: =LOOKUP(B$24,{0,1,2,3,4,5,6,7,8,9,10,11,12,"Q1","Q2","Q3","Q4"},{"ERROR",2,3,4,5,6,7,8,9,10,11,12,"Q1","Q2","Q3","Q4","Q1"}) -> Q1 | D24: =LOOKUP(C$24,{0,1,2,3,4,5,6,7,8,9,10,11,12,"Q1","Q2","Q3","Q4"},{"ERROR",2,3,4,5,6,7,8,9,10,11,12,"Q1","Q2","Q3","Q4","Q1"}) -> Q2 | E24: =LOOKUP(D$24,{0,1,2,3,4,5,6,7,8,9,10,11,12,"Q1","Q2","Q3","Q4"},{"ERROR",2,3,4,5,6,7,8,9,10,11,12,"Q1","Q2","Q3","Q4","Q1"}) -> Q3 | F24: =LOOKUP(E$24,{0,1,2,3,4,5,6,7,8,9,10,11,12,"Q1","Q2","Q3","Q4"},{"ERROR",2,3,4,5,6,7,8,9,10,11,12,"Q1","Q2","Q3","Q4","Q1"}) -> Q4 | G24: =LOOKUP(F$24,{0,1,2,3,4,5,6,7,8,9,10,11,12,"Q1","Q2","Q3","Q4"},{"ERROR",2,3,4,5,6,7,8,9,10,11,12,"Q1","Q2","Q3","Q4","Q1"}) -> Q1 | H24: =LOOKUP(G$24,{0,1,2,3,4,5,6,7,8,9,10,11,12,"Q1","Q2","Q3","Q4"},{"ERROR",2,3,4,5,6,7,8,9,10,11,12,"Q1","Q2","Q3","Q4","Q1"}) -> Q2 | I24: =LOOKUP(H$24,{0,1,2,3,4,5,6,7,8,9,10,11,12,"Q1","Q2","Q3","Q4"},{"ERROR",2,3,4,5,6,7,8,9,10,11,12,"Q1","Q2","Q3","Q4","Q1"}) -> Q3 | J24: =LOOKUP(I$24,{0,1,2,3,4,5,6,7,8,9,10,11,12,"Q1","Q2","Q3","Q4"},{"ERROR",2,3,4,5,6,7,8,9,10,11,12,"Q1","Q2","Q3","Q4","Q1"}) -> Q4 | ... M24: =LOOKUP(L$24,{0,1,2,3,4,5,6,7,8,9,10,11,12,"Q1","Q2","Q3","Q4"},{"ERROR",2,3,4,5,6,7,8,9,10,11,12,"Q1","Q2","Q3","Q4","Q1"}) -> Q3
B26: 0 | C26: 0 | D26: 0 | E26: 0 | F26: 0 | G26: 0 | H26: 0 | I26: 0 | J26: 0 | K26: 0 | L26: 0 | M26: 0 | N26: =SUM(B26:M26,N14) -> 396929.03
B29: =SUM(B25:B28) -> 0 | C29: =SUM(C25:C28) -> 0 | D29: =SUM(D25:D28) -> 0 | E29: =SUM(E25:E28) -> 0 | F29: =SUM(F25:F28) -> 0 | G29: =SUM(G25:G28) -> 0 | H29: =SUM(H25:H28) -> 0 | I29: =SUM(I25:I28) -> 0 | ... N29: =SUM(N25:N28) -> 396929.03
B31: =B29+N17 -> 396929.03 | C31: =C29+B31 -> 396929.03 | D31: =D29+C31 -> 396929.03 | E31: =E29+D31 -> 396929.03 | F31: =F29+E31 -> 396929.03 | G31: =G29+F31 -> 396929.03 | H31: =H29+G31 -> 396929.03 | I31: =I29+H31 -> 396929.03 | J31: =J29+I31 -> 396929.03 | ... M31: =M29+L31 -> 396929.03
A33: The header dates on this worksheet will automatically populate based on the start date of the job noted on the Job Initiation Form

Sheet Job Revision Form
B6: Capital Job Revision form
B7: Request for revision of existing Job
A8: Today's Date:
A9: Job #:
A10: Job Description (Short):
A12: Describe Change (Long):
A14: Division: | D14: Utility:
A16: Requested by: | D16: Project Manager:
A17: Requested by Description:
A19: Start Date: | B19: 39448 | D19: Est Completion Date: | E19: 39448
A21: Subclass: | D21: Subclass Cost Estimate | E21: 198464.52
E22: 198464.52
D26: Total Subclass Estimate | E26: =SUM(E21:E25) -> 396929.03
A27: Cost Estimate: | D27: Cost Est - Subclass Est | E27: =B27-E26 -> -396929.03
A29: Cash Flow Estimate:
A30: Description of retirements:
A32: Additional comments:
A34: Your name:
A36: THIS FORM IS NOT VALID WITHOUT APPROVING SIGNATURE OF GEORGE GORDON, PRESIDENT/CEO
A37: For use by DU President/CEO: | D37: For use by Accounting Office:
A38: Approved by: | D38: Updated Job #:
A39: Approved on: | D39: Date Job Changed:

Sheet Subclasses
A1: NAV Code | B1: Cost Center | C1: Description | D1: NARUC Codes | E1: GAAP Life | F1: Fed Tax MACRS Life | G1: Bonus Depr
A2: DHS 211 8 | B2: CHPP Plant | C2: Boiler Plant Equip - 75 years | D2: n/a | E2: 70 & 75 | F2: 20 | G2: Y
A3: DHS 212 8 | B3: CHPP Plant | C3: Boiler Plant Equip - 50 years | D3: n/a | E3: 50 | F3: 20 | G3: Y
A4: DHS 213 9 | B4: Coal Handling | C4: Boiler Plant Equipment - Other | D4: n/a | E4: 35 | F4: 20 | G4: Y
A5: DHS 214 8 | B5: CHPP Plant | C5: Boiler - Deaeriator | D5: n/a | E5: 35 | F5: 20 | G5: Y
A6: DHS 215 8 | B6: CHPP Plant | C6: Boiler - Feedwater Heaters | D6: n/a | E6: 35 | F6: 20 | G6: Y
A7: DHS 216 8 | B7: CHPP Plant | C7: Boiler - Feedwater Pump | D7: n/a | E7: 35 | F7: 20 | G7: Y
A8: DHS 221 4 | B8: Distribution | C8: Steam Meter Installations | D8: n/a | E8: 50 | F8: 20 | G8: Y
A9: DHS 222 4 | B9: Distribution | C9: Steam Meters | D9: n/a | E9: 20 & 25 | F9: 20 | G9: Y
A10: DHS 222 4.1 | B10: Distribution | C10: Steam Meter AMRs | D10: n/a | E10: 20 | F10: 20 | G10: Y
A11: DHS 231 4 | B11: Distribution | C11: CHPP Utilidors-Direct Buried- Condensate Lines | D11: n/a | E11: 40 | F11: 20 | G11: Y
A12: DHS 231 4.1 | B12: Distribution | C12: CHPP Utilidors - Condensate Lines | D12: n/a | E12: 40 | F12: 20 | G12: Y
A13: DHS 231 4.2 | B13: Distribution | C13: Direct Buried - Condensate Lines | D13: n/a | E13: 40 | F13: 20 | G13: Y
A14: DHS 232 4 | B14: Distribution | C14: CHPP Utilidors-Direct Buried- Steam Lines | D14: n/a | E14: 60 | F14: 20 | G14: Y
A15: DHS 232 4.1 | B15: Distribution | C15: CHPP Utilidors - Steam Lines | D15: n/a | E15: 60 | F15: 20 | G15: Y
A16: DHS 232 4.2 | B16: Distribution | C16: Direct Buried- Steam Lines | D16: n/a | E16: 60 | F16: 20 | G16: Y
A17: DHS 232 4.3 | B17: Distribution | C17: Utilidors - Steam Traps | D17: n/a | E17: 20 & 25 | F17: 20 | G17: Y
A18: DHS 235 8 | B18: CHPP Plant | C18: Wells and Springs | D18: n/a | E18: 45 | F18: 20 | G18: Y
A19: DHS 242 8 | B19: CHPP Plant | C19: Other-Fuel Holders, Producer | D19: n/a | E19: 55 | F19: 20 | G19: Y
A20: DHS 261 8 | B20: CHPP Plant | C20: Turbogenerator Unit | D20: n/a | E20: 75 | F20: 20 | G20: Y
A21: DHS 261 8.1 | B21: CHPP Plant | C21: Steam Turbines | D21: n/a | E21: 75 | F21: 20 | G21: Y
A22: DHS 261 8.2 | B22: CHPP Plant | C22: Generators | D22: n/a | E22: 75 | F22: 20 | G22: Y
A23: DHS 261 8.3 | B23: CHPP Plant | C23: Black Start Generators | D23: n/a | E23: 75 | F23: 20 | G23: Y
A24: DHS 262 8 | B24: CHPP Plant | C24: Engine Driven Generators | D24: n/a | E24: 75 | F24: 20 | G24: Y
A25: DHS 263 8 | B25: CHPP Plant | C25: Accessory Electric Equipment | D25: n/a | E25: 40 | F25: 20 | G25: Y
A26: DHS 264 8 | B26: CHPP Plant | C26: Other Systems | D26: n/a | E26: 35 & 40 | F26: 20 | G26: Y
A27: DHS 271 3 | B27: Water Treatment | C27: Chemical Feed System | D27: n/a | E27: 35 | F27: 20 | G27: Y
A28: DHS 272 3 | B28: Water Treatment | C28: Condensate Polisher | D28: n/a | E28: 35 | F28: 20 | G28: Y
A29: DHS 273 3 | B29: Water Treatment | C29: Condensate Pumps-Storage Tanks | D29: n/a | E29: 35 | F29: 20 | G29: Y
A30: DHS 274 3 | B30: Water Treatment | C30: Manholes | D30: n/a | E30: 35 | F30: 20 | G30: Y
A31: DHS 281 9 | B31: Coal Handling | C31: Bucket Elevators | D31: n/a | E31: 40 | F31: 20 | G31: Y
A32: DHS 282 9 | B32: Coal Handling | C32: Coal Conveyers | D32: n/a | E32: 40 | F32: 20 | G32: Y
A33: DHS 283 9 | B33: Coal Handling | C33: Coal Crushers | D33: n/a | E33: 40 | F33: 20 | G33: Y
A34: DHS 283 9.1 | B34: Coal Handling | C34: Coal System Dust Collectors | D34: n/a | E34: 40 | F34: 20 | G34: Y
A35: DHS 284 9 | B35: Coal Handling | C35: Coal Feeders | D35: n/a | E35: 40 | F35: 20 | G35: Y
A36: DHS 285 9 | B36: Coal Handling | C36: Screening System | D36: n/a | E36: 40 | F36: 20 | G36: Y
A37: DHS 286 9 | B37: Coal Handling | C37: Track Mobile | D37: n/a | E37: 75 | F37: 20 | G37: Y
A38: DHS 287 9 | B38: Coal Handling | C38: Other Equip | D38: n/a | E38: 40 | F38: 20 | G38: Y
... A52: DHS 351 5 | B52: General Plant | C52: Plant Equipment | D52: n/a | E52: 35 | F52: 20 | G52: Y
A53: DHS 352 5 | B53: General Plant | C53: Transportation Equipment | D53: n/a | E53: 10, 15, 20 & 30 | F53: 7 | G53: Y
...

Sheet Job Completion Form
B6: Job Completion form
B7: Notification of Job Completion
A8: Today's Date:
A9: Job #:
A10: Job Description (Short):
A12: Describe Job (Long):
A14: Division: | B14: 1 | D14: Utility: | E14: 1
A16: Requested by: | D16: Project Manager:
A17: Requested by Description:
A19: Start Date: | B19: 39448 | D19: Final Completion Date: | E19: 39448
A21: Short Description | B21: Subclass | C21: Qty | D21: Expected Life (yrs) | E21: Subclass Final Cost
D27: Total Subclass Cost | E27: =SUM(E22:E26) -> 0
A28: Final Cost: | D28: Cost - Subclass | E28: =B28-E27 -> 0
A30: Description of retirements:
A32: Additional comments:
A34: Your name:
A36: THIS FORM IS NOT VALID WITHOUT APPROVING SIGNATURE OF GEORGE GORDON, PRESIDENT/CEO
A37: For use by DU President/CEO: | D37: For use by Accounting Office:
A38: Approved by: | D38: Associated FA #:
A39: Approved on: | D39: Date Job Closed:

Sheet form picklists
A1: Division | C1: Utility | E1: Requested By | G1: NAV Code | H1: Cost Center | I1: Description | K1: Cash Flow? | M1: CPM? | O1: CFID | P1: Division | Q1: CFID2 | R1: Utility
A3: Corporate | C3: Central Heating Plant | E3: 1. Original Contract | G3: DHS 211 8 | H3: CHPP Plant | I3: Boiler Plant Equip - 75 years | K3: See Attached | M3: Yes | O3: 1 | P3: N/A | Q3: 1 | R3: N/A
A4: Fort Greely | C4: Corporate | E4: 2. Contract Mod | G4: DHS 212 8 | H4: CHPP Plant | I4: Boiler Plant Equip - 50 years | K4: N/A | M4: No | O4: 2 | P4: Corporate | Q4: 2 | R4: Central Heating Plant
A5: Fort Richardson | C5: Electric Distribution | E5: 3. COR MOD | G5: DHS 213 9 | H5: Coal Handling | I5: Boiler Plant Equipment - Other | O5: 3 | P5: Fort Greely | Q5: 3 | R5: Corporate
A6: Fort Wainwright | C6: Natural Gas | E6: 4. Other MOD | G6: DHS 214 8 | H6: CHPP Plant | I6: Boiler - Deaeriator | O6: 4 | P6: Fort Richardson | Q6: 4 | R6: Electric Distribution
C7: Waste Water | E7: 5. Corporate | G7: DHS 215 8 | H7: CHPP Plant | I7: Boiler - Feedwater Heaters | O7: 5 | P7: Fort Wainwright | Q7: 5 | R7: Natural Gas
C8: Water | E8: 6. An Individual | G8: DHS 216 8 | H8: CHPP Plant | I8: Boiler - Feedwater Pump | Q8: 6 | R8: Waste Water
G9: DHS 221 4 | H9: Distribution | I9: Steam Meter Installations | Q9: 7 | R9: Water
G10: DHS 222 4 | H10: Distribution | I10: Steam Meters
G11: DHS 222 4.1 | H11: Distribution | I11: Steam Meter AMRs
G12: DHS 231 4 | H12: Distribution | I12: CHPP Utilidors-Direct Buried- Condensate Lines
G13: DHS 231 4.1 | H13: Distribution | I13: CHPP Utilidors - Condensate Lines
G14: DHS 231 4.2 | H14: Distribution | I14: Direct Buried - Condensate Lines
G15: DHS 232 4 | H15: Distribution | I15: CHPP Utilidors-Direct Buried- Steam Lines
G16: DHS 232 4.1 | H16: Distribution | I16: CHPP Utilidors - Steam Lines
G17: DHS 232 4.2 | H17: Distribution | I17: Direct Buried- Steam Lines
G18: DHS 232 4.3 | H18: Distribution | I18: Utilidors - Steam Traps
G19: DHS 235 8 | H19: CHPP Plant | I19: Wells and Springs
G20: DHS 242 8 | H20: CHPP Plant | I20: Other-Fuel Holders, Producer
G21: DHS 261 8 | H21: CHPP Plant | I21: Turbogenerator Unit
... G260: WWC 398 7 | H260: General Plant | I260: Other Tangible Equipment
