Workbook
Name _EAR01: #REF!
Name _EAR02: #REF!
Name _EAR03: #REF!
Name _EAR04: #REF!
Name _EAR05: #REF!
Name _EAR06: #REF!
Name _EAR07: #REF!
Name _EAR08: #REF!
Name _EAR09: #REF!
Name _EAR10: #REF!
Name _LR01: #REF!
Name _LR02: #REF!
Name _LR03: #REF!
Name _LR04: #REF!
Name _LR05: #REF!
Name _LR06: #REF!
Name _LR07: #REF!
Name _LR08: #REF!
Name _LR09: #REF!
Name _LR10: #REF!
Name _OSR01: #REF!
Name _OSR02: #REF!
Name _OSR03: #REF!
Name _OSR04: #REF!
Name _OSR05: #REF!
Name _OSR06: #REF!
Name _OSR07: #REF!
Name _OSR08: #REF!
Name _OSR09: #REF!
Name _OSR10: #REF!
Name Area: #REF!
Name AvgFlow: #REF!
Name Basis: #REF!
Name Cell01: '[1]A2-Task'!$A$3
Name Cell02: '[1]A2-Task'!$A$4
Name Cell03: '[1]A2-Task'!$A$5
Name Cell04: '[1]A2-Task'!$A$6
Name Cell05: '[1]A2-Task'!$A$7
Name Cell06: '[1]A2-Task'!$A$8
Name Cell07: '[1]A2-Task'!$A$9
Name Cell08: '[1]A2-Task'!$A$10
Name Cell09: '[1]A2-Task'!$A$11
Name Cell10: '[1]A2-Task'!$A$12
Name CHANGES: #REF!
Name Clear: #REF!
Name Clear_0Summary: #REF!
Name Clear_5Staff: #REF!
Name Clear_EarnedValue: #REF!
Name Clear_Staff: '[1]A3-Staff'!#REF!
Name data: #REF!
Name DigFeed: #REF!
Name DigFlow: #REF!
Name digOut: #REF!
Name DigVol: #REF!
Name DigWarn: #REF!
Name EAR: #REF!
Name Exp_Revenue01: '[1]A5-Expense'!$C$149
Name Exp_Revenue02: '[1]A5-Expense'!$D$149
Name Exp_Revenue03: '[1]A5-Expense'!$E$149
Name Exp_Revenue04: '[1]A5-Expense'!$F$149

Sheet Richardson Elec Dist- R&R Proj
A1: Fort Richardson Electrical Distribution R&R Projects
A4: Project Number: Year 2
A5: Project Title: Upgrade Water System
A6: Year That Payment for Project Will Begin: Year 2 of the 50 Year Contract
A8: Project Description | B8: Year Implemented | C8: Year Payments Begin | D8: Quantity | E8: Unit of Measure | F8: Cost/UOM | G8: Base Constr Cost (no markups) | H8: Contingency | I8: Bonds, Insurance | J8: General Conditions | K8: G & A | L8: Profit | M8: Total Capital Cost | N8: Studies plus Predesign | O8: Design | P8: SDC | Q8: Fee on Professional Services | R8: Total Project Cost | T8: Engineering | U8: Construction | V8: GM
H9: 0.05 | I9: 0.02 | J9: 0.05 | K9: 0.122 | L9: 0.1 | N9: 0.077 | O9: 0.05 | P9: 0.03 | Q9: 0.1
A11: - | B11: =#REF! -> #REF! | C11: In Initial Replacements | G11: =SUMIF(#REF!,$B11,#REF!) -> #REF! | H11: =G11*$H$9 -> #REF! | I11: =SUM(G11:H11)*I$9 -> #REF! | J11: =SUM(G11:I11)*J$9 -> #REF! | K11: =SUM(G11:J11)*K$9 -> #REF! | L11: =SUM(G11:K11)*L$9 -> #REF! | M11: =SUM(G11:L11) -> #REF! | N11: =M11*N$9 -> #REF! | O11: =M11*O$9 -> #REF! | P11: =M11*P$9 -> #REF! | Q11: =SUM(N11:P11)*Q$9 -> #REF! | R11: =SUM(M11:Q11) -> #REF! | T11: =SUM(N11:Q11)*$S$69 -> #REF! | U11: =M11*$S$69 -> #REF! | V11: =(K11+L11+Q11)*S$69 -> #REF!
A12: - | B12: =B11+1 -> #REF! | C12: In Initial Replacements | G12: =SUMIF(#REF!,$B12,#REF!) -> #REF! | H12: =G12*$H$9 -> #REF! | I12: =SUM(G12:H12)*I$9 -> #REF! | J12: =SUM(G12:I12)*J$9 -> #REF! | K12: =SUM(G12:J12)*K$9 -> #REF! | L12: =SUM(G12:K12)*L$9 -> #REF! | M12: =SUM(G12:L12) -> #REF! | N12: =M12*N$9 -> #REF! | O12: =M12*O$9 -> #REF! | P12: =M12*P$9 -> #REF! | Q12: =SUM(N12:P12)*Q$9 -> #REF! | R12: =SUM(M12:Q12) -> #REF! | T12: =SUM(N12:Q12)*$S$69 -> #REF! | U12: =M12*$S$69 -> #REF! | V12: =(K12+L12+Q12)*S$69 -> #REF!
A13: - | B13: =B12+1 -> #REF! | C13: In Initial Replacements | G13: =SUMIF(#REF!,$B13,#REF!) -> #REF! | H13: =G13*$H$9 -> #REF! | I13: =SUM(G13:H13)*I$9 -> #REF! | J13: =SUM(G13:I13)*J$9 -> #REF! | K13: =SUM(G13:J13)*K$9 -> #REF! | L13: =SUM(G13:K13)*L$9 -> #REF! | M13: =SUM(G13:L13) -> #REF! | N13: =M13*N$9 -> #REF! | O13: =M13*O$9 -> #REF! | P13: =M13*P$9 -> #REF! | Q13: =SUM(N13:P13)*Q$9 -> #REF! | R13: =SUM(M13:Q13) -> #REF! | T13: =SUM(N13:Q13)*$S$69 -> #REF! | U13: =M13*$S$69 -> #REF! | V13: =(K13+L13+Q13)*S$69 -> #REF!
A14: - | B14: =B13+1 -> #REF! | C14: In Initial Replacements | G14: =SUMIF(#REF!,$B14,#REF!) -> #REF! | H14: =G14*$H$9 -> #REF! | I14: =SUM(G14:H14)*I$9 -> #REF! | J14: =SUM(G14:I14)*J$9 -> #REF! | K14: =SUM(G14:J14)*K$9 -> #REF! | L14: =SUM(G14:K14)*L$9 -> #REF! | M14: =SUM(G14:L14) -> #REF! | N14: =M14*N$9 -> #REF! | O14: =M14*O$9 -> #REF! | P14: =M14*P$9 -> #REF! | Q14: =SUM(N14:P14)*Q$9 -> #REF! | R14: =SUM(M14:Q14) -> #REF!
A15: - | B15: =B14+1 -> #REF! | C15: In Initial Replacements | G15: =SUMIF(#REF!,$B15,#REF!) -> #REF! | H15: =G15*$H$9 -> #REF! | I15: =SUM(G15:H15)*I$9 -> #REF! | J15: =SUM(G15:I15)*J$9 -> #REF! | K15: =SUM(G15:J15)*K$9 -> #REF! | L15: =SUM(G15:K15)*L$9 -> #REF! | M15: =SUM(G15:L15) -> #REF! | N15: =M15*N$9 -> #REF! | O15: =M15*O$9 -> #REF! | P15: =M15*P$9 -> #REF! | Q15: =SUM(N15:P15)*Q$9 -> #REF! | R15: =SUM(M15:Q15) -> #REF!
B16: =B15+1 -> #REF! | C16: =B16+1 -> #REF! | G16: =SUMIF(#REF!,$B16,#REF!) -> #REF! | H16: =G16*$H$9 -> #REF! | I16: =SUM(G16:H16)*I$9 -> #REF! | J16: =SUM(G16:I16)*J$9 -> #REF! | K16: =SUM(G16:J16)*K$9 -> #REF! | L16: =SUM(G16:K16)*L$9 -> #REF! | M16: =SUM(G16:L16) -> #REF! | N16: =M16*N$9 -> #REF! | O16: =M16*O$9 -> #REF! | P16: =M16*P$9 -> #REF! | Q16: =SUM(N16:P16)*Q$9 -> #REF! | R16: =SUM(M16:Q16) -> #REF!
B17: =B16+1 -> #REF! | C17: =B17+1 -> #REF! | G17: =SUMIF(#REF!,$B17,#REF!) -> #REF! | H17: =G17*$H$9 -> #REF! | I17: =SUM(G17:H17)*I$9 -> #REF! | J17: =SUM(G17:I17)*J$9 -> #REF! | K17: =SUM(G17:J17)*K$9 -> #REF! | L17: =SUM(G17:K17)*L$9 -> #REF! | M17: =SUM(G17:L17) -> #REF! | N17: =M17*N$9 -> #REF! | O17: =M17*O$9 -> #REF! | P17: =M17*P$9 -> #REF! | Q17: =SUM(N17:P17)*Q$9 -> #REF! | R17: =SUM(M17:Q17) -> #REF!
B18: =B17+1 -> #REF! | C18: =B18+1 -> #REF! | G18: =SUMIF(#REF!,$B18,#REF!) -> #REF! | H18: =G18*$H$9 -> #REF! | I18: =SUM(G18:H18)*I$9 -> #REF! | J18: =SUM(G18:I18)*J$9 -> #REF! | K18: =SUM(G18:J18)*K$9 -> #REF! | L18: =SUM(G18:K18)*L$9 -> #REF! | M18: =SUM(G18:L18) -> #REF! | N18: =M18*N$9 -> #REF! | O18: =M18*O$9 -> #REF! | P18: =M18*P$9 -> #REF! | Q18: =SUM(N18:P18)*Q$9 -> #REF! | R18: =SUM(M18:Q18) -> #REF!
B19: =B18+1 -> #REF! | C19: =B19+1 -> #REF! | G19: =SUMIF(#REF!,$B19,#REF!) -> #REF! | H19: =G19*$H$9 -> #REF! | I19: =SUM(G19:H19)*I$9 -> #REF! | J19: =SUM(G19:I19)*J$9 -> #REF! | K19: =SUM(G19:J19)*K$9 -> #REF! | L19: =SUM(G19:K19)*L$9 -> #REF! | M19: =SUM(G19:L19) -> #REF! | N19: =M19*N$9 -> #REF! | O19: =M19*O$9 -> #REF! | P19: =M19*P$9 -> #REF! | Q19: =SUM(N19:P19)*Q$9 -> #REF! | R19: =SUM(M19:Q19) -> #REF!
B20: =B19+1 -> #REF! | C20: =B20+1 -> #REF! | G20: =SUMIF(#REF!,$B20,#REF!) -> #REF! | H20: =G20*$H$9 -> #REF! | I20: =SUM(G20:H20)*I$9 -> #REF! | J20: =SUM(G20:I20)*J$9 -> #REF! | K20: =SUM(G20:J20)*K$9 -> #REF! | L20: =SUM(G20:K20)*L$9 -> #REF! | M20: =SUM(G20:L20) -> #REF! | N20: =M20*N$9 -> #REF! | O20: =M20*O$9 -> #REF! | P20: =M20*P$9 -> #REF! | Q20: =SUM(N20:P20)*Q$9 -> #REF! | R20: =SUM(M20:Q20) -> #REF!
B21: =B20+1 -> #REF! | C21: =B21+1 -> #REF! | G21: =SUMIF(#REF!,$B21,#REF!) -> #REF! | H21: =G21*$H$9 -> #REF! | I21: =SUM(G21:H21)*I$9 -> #REF! | J21: =SUM(G21:I21)*J$9 -> #REF! | K21: =SUM(G21:J21)*K$9 -> #REF! | L21: =SUM(G21:K21)*L$9 -> #REF! | M21: =SUM(G21:L21) -> #REF! | N21: =M21*N$9 -> #REF! | O21: =M21*O$9 -> #REF! | P21: =M21*P$9 -> #REF! | Q21: =SUM(N21:P21)*Q$9 -> #REF! | R21: =SUM(M21:Q21) -> #REF!
B22: =B21+1 -> #REF! | C22: =B22+1 -> #REF! | G22: =SUMIF(#REF!,$B22,#REF!) -> #REF! | H22: =G22*$H$9 -> #REF! | I22: =SUM(G22:H22)*I$9 -> #REF! | J22: =SUM(G22:I22)*J$9 -> #REF! | K22: =SUM(G22:J22)*K$9 -> #REF! | L22: =SUM(G22:K22)*L$9 -> #REF! | M22: =SUM(G22:L22) -> #REF! | N22: =M22*N$9 -> #REF! | O22: =M22*O$9 -> #REF! | P22: =M22*P$9 -> #REF! | Q22: =SUM(N22:P22)*Q$9 -> #REF! | R22: =SUM(M22:Q22) -> #REF!
B23: =B22+1 -> #REF! | C23: =B23+1 -> #REF! | G23: =SUMIF(#REF!,$B23,#REF!) -> #REF! | H23: =G23*$H$9 -> #REF! | I23: =SUM(G23:H23)*I$9 -> #REF! | J23: =SUM(G23:I23)*J$9 -> #REF! | K23: =SUM(G23:J23)*K$9 -> #REF! | L23: =SUM(G23:K23)*L$9 -> #REF! | M23: =SUM(G23:L23) -> #REF! | N23: =M23*N$9 -> #REF! | O23: =M23*O$9 -> #REF! | P23: =M23*P$9 -> #REF! | Q23: =SUM(N23:P23)*Q$9 -> #REF! | R23: =SUM(M23:Q23) -> #REF!
B24: =B23+1 -> #REF! | C24: =B24+1 -> #REF! | G24: =SUMIF(#REF!,$B24,#REF!) -> #REF! | H24: =G24*$H$9 -> #REF! | I24: =SUM(G24:H24)*I$9 -> #REF! | J24: =SUM(G24:I24)*J$9 -> #REF! | K24: =SUM(G24:J24)*K$9 -> #REF! | L24: =SUM(G24:K24)*L$9 -> #REF! | M24: =SUM(G24:L24) -> #REF! | N24: =M24*N$9 -> #REF! | O24: =M24*O$9 -> #REF! | P24: =M24*P$9 -> #REF! | Q24: =SUM(N24:P24)*Q$9 -> #REF! | R24: =SUM(M24:Q24) -> #REF!
B25: =B24+1 -> #REF! | C25: =B25+1 -> #REF! | G25: =SUMIF(#REF!,$B25,#REF!) -> #REF! | H25: =G25*$H$9 -> #REF! | I25: =SUM(G25:H25)*I$9 -> #REF! | J25: =SUM(G25:I25)*J$9 -> #REF! | K25: =SUM(G25:J25)*K$9 -> #REF! | L25: =SUM(G25:K25)*L$9 -> #REF! | M25: =SUM(G25:L25) -> #REF! | N25: =M25*N$9 -> #REF! | O25: =M25*O$9 -> #REF! | P25: =M25*P$9 -> #REF! | Q25: =SUM(N25:P25)*Q$9 -> #REF! | R25: =SUM(M25:Q25) -> #REF!
B26: =B25+1 -> #REF! | C26: =B26+1 -> #REF! | G26: =SUMIF(#REF!,$B26,#REF!) -> #REF! | H26: =G26*$H$9 -> #REF! | I26: =SUM(G26:H26)*I$9 -> #REF! | J26: =SUM(G26:I26)*J$9 -> #REF! | K26: =SUM(G26:J26)*K$9 -> #REF! | L26: =SUM(G26:K26)*L$9 -> #REF! | M26: =SUM(G26:L26) -> #REF! | N26: =M26*N$9 -> #REF! | O26: =M26*O$9 -> #REF! | P26: =M26*P$9 -> #REF! | Q26: =SUM(N26:P26)*Q$9 -> #REF! | R26: =SUM(M26:Q26) -> #REF!
B27: =B26+1 -> #REF! | C27: =B27+1 -> #REF! | G27: =SUMIF(#REF!,$B27,#REF!) -> #REF! | H27: =G27*$H$9 -> #REF! | I27: =SUM(G27:H27)*I$9 -> #REF! | J27: =SUM(G27:I27)*J$9 -> #REF! | K27: =SUM(G27:J27)*K$9 -> #REF! | L27: =SUM(G27:K27)*L$9 -> #REF! | M27: =SUM(G27:L27) -> #REF! | N27: =M27*N$9 -> #REF! | O27: =M27*O$9 -> #REF! | P27: =M27*P$9 -> #REF! | Q27: =SUM(N27:P27)*Q$9 -> #REF! | R27: =SUM(M27:Q27) -> #REF!
... B61: =B60+1 -> #REF! | C61: =B61+1 -> #REF! | G61: =SUMIF(#REF!,$B61,#REF!) -> #REF! | H61: =G61*$H$9 -> #REF! | I61: =SUM(G61:H61)*I$9 -> #REF! | J61: =SUM(G61:I61)*J$9 -> #REF! | K61: =SUM(G61:J61)*K$9 -> #REF! | L61: =SUM(G61:K61)*L$9 -> #REF! | M61: =SUM(G61:L61) -> #REF! | N61: =M61*N$9 -> #REF! | O61: =M61*O$9 -> #REF! | P61: =M61*P$9 -> #REF! | Q61: =SUM(N61:P61)*Q$9 -> #REF! | R61: =SUM(M61:Q61) -> #REF!
H62: =G62*$H$9 -> 0 | I62: =SUM(G62:H62)*I$9 -> 0 | J62: =SUM(G62:I62)*J$9 -> 0 | K62: =SUM(G62:J62)*K$9 -> 0 | L62: =SUM(G62:K62)*L$9 -> 0 | M62: =SUM(G62:L62) -> 0 | N62: =M62*N$9 -> 0 | O62: =M62*O$9 -> 0 | P62: =M62*P$9 -> 0 | Q62: =SUM(N62:P62)*Q$9 -> 0 | R62: =SUM(M62:Q62) -> 0 | T62: =SUM(N62:Q62)*$S$69 -> 0 | U62: =M62*$S$69 -> 0 | V62: =(K62+L62+Q62)*S$69 -> 0
A64: Summary Water Distribution | G64: =SUM(G11:G62) -> #REF! | H64: =SUM(H11:H62) -> #REF! | I64: =SUM(I11:I62) -> #REF! | J64: =SUM(J11:J62) -> #REF! | K64: =SUM(K11:K62) -> #REF! | L64: =SUM(L11:L62) -> #REF! | M64: =SUM(M11:M62) -> #REF! | N64: =SUM(N11:N62) -> #REF! | ... R64: =SUM(R11:R62) -> #REF!

Sheet Richardson NatG Dist- R&R Proj
A1: Fort Richardson Natural Gas Distribution R&R Projects
A4: Project Number: Year 2
A5: Project Title: Upgrade Water System
A6: Year That Payment for Project Will Begin: Year 2 of the 50 Year Contract
A8: Project Description | B8: Year Implemented | C8: Year Payments Begin | D8: Quantity | E8: Unit of Measure | F8: Cost/UOM | G8: Base Constr Cost (no markups) | H8: Contingency | I8: Bonds, Insurance | J8: General Conditions | K8: G & A | L8: Profit | M8: Total Capital Cost | N8: Studies plus Predesign | O8: Design | P8: SDC | Q8: Fee on Professional Services | R8: Total Project Cost | T8: Engineering | U8: Construction | V8: GM
H9: 0.05 | I9: 0.02 | J9: 0.05 | K9: 0.122 | L9: 0.1 | N9: 0.077 | O9: 0.05 | P9: 0.03 | Q9: 0.1
A11: - | B11: =#REF! -> #REF! | C11: In Initial Replacements | G11: =SUMIF(#REF!,$B11,#REF!) -> #REF! | H11: =G11*$H$9 -> #REF! | I11: =SUM(G11:H11)*I$9 -> #REF! | J11: =SUM(G11:I11)*J$9 -> #REF! | K11: =SUM(G11:J11)*K$9 -> #REF! | L11: =SUM(G11:K11)*L$9 -> #REF! | M11: =SUM(G11:L11) -> #REF! | N11: =M11*N$9 -> #REF! | O11: =M11*O$9 -> #REF! | P11: =M11*P$9 -> #REF! | Q11: =SUM(N11:P11)*Q$9 -> #REF! | R11: =SUM(M11:Q11) -> #REF! | T11: =SUM(N11:Q11)*$S$69 -> #REF! | U11: =M11*$S$69 -> #REF! | V11: =(K11+L11+Q11)*S$69 -> #REF!
A12: - | B12: =B11+1 -> #REF! | C12: In Initial Replacements | G12: =SUMIF(#REF!,$B12,#REF!) -> #REF! | H12: =G12*$H$9 -> #REF! | I12: =SUM(G12:H12)*I$9 -> #REF! | J12: =SUM(G12:I12)*J$9 -> #REF! | K12: =SUM(G12:J12)*K$9 -> #REF! | L12: =SUM(G12:K12)*L$9 -> #REF! | M12: =SUM(G12:L12) -> #REF! | N12: =M12*N$9 -> #REF! | O12: =M12*O$9 -> #REF! | P12: =M12*P$9 -> #REF! | Q12: =SUM(N12:P12)*Q$9 -> #REF! | R12: =SUM(M12:Q12) -> #REF! | T12: =SUM(N12:Q12)*$S$69 -> #REF! | U12: =M12*$S$69 -> #REF! | V12: =(K12+L12+Q12)*S$69 -> #REF!
A13: - | B13: =B12+1 -> #REF! | C13: In Initial Replacements | G13: =SUMIF(#REF!,$B13,#REF!) -> #REF! | H13: =G13*$H$9 -> #REF! | I13: =SUM(G13:H13)*I$9 -> #REF! | J13: =SUM(G13:I13)*J$9 -> #REF! | K13: =SUM(G13:J13)*K$9 -> #REF! | L13: =SUM(G13:K13)*L$9 -> #REF! | M13: =SUM(G13:L13) -> #REF! | N13: =M13*N$9 -> #REF! | O13: =M13*O$9 -> #REF! | P13: =M13*P$9 -> #REF! | Q13: =SUM(N13:P13)*Q$9 -> #REF! | R13: =SUM(M13:Q13) -> #REF! | T13: =SUM(N13:Q13)*$S$69 -> #REF! | U13: =M13*$S$69 -> #REF! | V13: =(K13+L13+Q13)*S$69 -> #REF!
A14: - | B14: =B13+1 -> #REF! | C14: In Initial Replacements | G14: =SUMIF(#REF!,$B14,#REF!) -> #REF! | H14: =G14*$H$9 -> #REF! | I14: =SUM(G14:H14)*I$9 -> #REF! | J14: =SUM(G14:I14)*J$9 -> #REF! | K14: =SUM(G14:J14)*K$9 -> #REF! | L14: =SUM(G14:K14)*L$9 -> #REF! | M14: =SUM(G14:L14) -> #REF! | N14: =M14*N$9 -> #REF! | O14: =M14*O$9 -> #REF! | P14: =M14*P$9 -> #REF! | Q14: =SUM(N14:P14)*Q$9 -> #REF! | R14: =SUM(M14:Q14) -> #REF!
A15: - | B15: =B14+1 -> #REF! | C15: In Initial Replacements | G15: =SUMIF(#REF!,$B15,#REF!) -> #REF! | H15: =G15*$H$9 -> #REF! | I15: =SUM(G15:H15)*I$9 -> #REF! | J15: =SUM(G15:I15)*J$9 -> #REF! | K15: =SUM(G15:J15)*K$9 -> #REF! | L15: =SUM(G15:K15)*L$9 -> #REF! | M15: =SUM(G15:L15) -> #REF! | N15: =M15*N$9 -> #REF! | O15: =M15*O$9 -> #REF! | P15: =M15*P$9 -> #REF! | Q15: =SUM(N15:P15)*Q$9 -> #REF! | R15: =SUM(M15:Q15) -> #REF!
B16: =B15+1 -> #REF! | C16: =B16+1 -> #REF! | G16: =SUMIF(#REF!,$B16,#REF!) -> #REF! | H16: =G16*$H$9 -> #REF! | I16: =SUM(G16:H16)*I$9 -> #REF! | J16: =SUM(G16:I16)*J$9 -> #REF! | K16: =SUM(G16:J16)*K$9 -> #REF! | L16: =SUM(G16:K16)*L$9 -> #REF! | M16: =SUM(G16:L16) -> #REF! | N16: =M16*N$9 -> #REF! | O16: =M16*O$9 -> #REF! | P16: =M16*P$9 -> #REF! | Q16: =SUM(N16:P16)*Q$9 -> #REF! | R16: =SUM(M16:Q16) -> #REF!
B17: =B16+1 -> #REF! | C17: =B17+1 -> #REF! | G17: =SUMIF(#REF!,$B17,#REF!) -> #REF! | H17: =G17*$H$9 -> #REF! | I17: =SUM(G17:H17)*I$9 -> #REF! | J17: =SUM(G17:I17)*J$9 -> #REF! | K17: =SUM(G17:J17)*K$9 -> #REF! | L17: =SUM(G17:K17)*L$9 -> #REF! | M17: =SUM(G17:L17) -> #REF! | N17: =M17*N$9 -> #REF! | O17: =M17*O$9 -> #REF! | P17: =M17*P$9 -> #REF! | Q17: =SUM(N17:P17)*Q$9 -> #REF! | R17: =SUM(M17:Q17) -> #REF!
B18: =B17+1 -> #REF! | C18: =B18+1 -> #REF! | G18: =SUMIF(#REF!,$B18,#REF!) -> #REF! | H18: =G18*$H$9 -> #REF! | I18: =SUM(G18:H18)*I$9 -> #REF! | J18: =SUM(G18:I18)*J$9 -> #REF! | K18: =SUM(G18:J18)*K$9 -> #REF! | L18: =SUM(G18:K18)*L$9 -> #REF! | M18: =SUM(G18:L18) -> #REF! | N18: =M18*N$9 -> #REF! | O18: =M18*O$9 -> #REF! | P18: =M18*P$9 -> #REF! | Q18: =SUM(N18:P18)*Q$9 -> #REF! | R18: =SUM(M18:Q18) -> #REF!
B19: =B18+1 -> #REF! | C19: =B19+1 -> #REF! | G19: =SUMIF(#REF!,$B19,#REF!) -> #REF! | H19: =G19*$H$9 -> #REF! | I19: =SUM(G19:H19)*I$9 -> #REF! | J19: =SUM(G19:I19)*J$9 -> #REF! | K19: =SUM(G19:J19)*K$9 -> #REF! | L19: =SUM(G19:K19)*L$9 -> #REF! | M19: =SUM(G19:L19) -> #REF! | N19: =M19*N$9 -> #REF! | O19: =M19*O$9 -> #REF! | P19: =M19*P$9 -> #REF! | Q19: =SUM(N19:P19)*Q$9 -> #REF! | R19: =SUM(M19:Q19) -> #REF!
B20: =B19+1 -> #REF! | C20: =B20+1 -> #REF! | G20: =SUMIF(#REF!,$B20,#REF!) -> #REF! | H20: =G20*$H$9 -> #REF! | I20: =SUM(G20:H20)*I$9 -> #REF! | J20: =SUM(G20:I20)*J$9 -> #REF! | K20: =SUM(G20:J20)*K$9 -> #REF! | L20: =SUM(G20:K20)*L$9 -> #REF! | M20: =SUM(G20:L20) -> #REF! | N20: =M20*N$9 -> #REF! | O20: =M20*O$9 -> #REF! | P20: =M20*P$9 -> #REF! | Q20: =SUM(N20:P20)*Q$9 -> #REF! | R20: =SUM(M20:Q20) -> #REF!
B21: =B20+1 -> #REF! | C21: =B21+1 -> #REF! | G21: =SUMIF(#REF!,$B21,#REF!) -> #REF! | H21: =G21*$H$9 -> #REF! | I21: =SUM(G21:H21)*I$9 -> #REF! | J21: =SUM(G21:I21)*J$9 -> #REF! | K21: =SUM(G21:J21)*K$9 -> #REF! | L21: =SUM(G21:K21)*L$9 -> #REF! | M21: =SUM(G21:L21) -> #REF! | N21: =M21*N$9 -> #REF! | O21: =M21*O$9 -> #REF! | P21: =M21*P$9 -> #REF! | Q21: =SUM(N21:P21)*Q$9 -> #REF! | R21: =SUM(M21:Q21) -> #REF!
B22: =B21+1 -> #REF! | C22: =B22+1 -> #REF! | G22: =SUMIF(#REF!,$B22,#REF!) -> #REF! | H22: =G22*$H$9 -> #REF! | I22: =SUM(G22:H22)*I$9 -> #REF! | J22: =SUM(G22:I22)*J$9 -> #REF! | K22: =SUM(G22:J22)*K$9 -> #REF! | L22: =SUM(G22:K22)*L$9 -> #REF! | M22: =SUM(G22:L22) -> #REF! | N22: =M22*N$9 -> #REF! | O22: =M22*O$9 -> #REF! | P22: =M22*P$9 -> #REF! | Q22: =SUM(N22:P22)*Q$9 -> #REF! | R22: =SUM(M22:Q22) -> #REF!
B23: =B22+1 -> #REF! | C23: =B23+1 -> #REF! | G23: =SUMIF(#REF!,$B23,#REF!) -> #REF! | H23: =G23*$H$9 -> #REF! | I23: =SUM(G23:H23)*I$9 -> #REF! | J23: =SUM(G23:I23)*J$9 -> #REF! | K23: =SUM(G23:J23)*K$9 -> #REF! | L23: =SUM(G23:K23)*L$9 -> #REF! | M23: =SUM(G23:L23) -> #REF! | N23: =M23*N$9 -> #REF! | O23: =M23*O$9 -> #REF! | P23: =M23*P$9 -> #REF! | Q23: =SUM(N23:P23)*Q$9 -> #REF! | R23: =SUM(M23:Q23) -> #REF!
B24: =B23+1 -> #REF! | C24: =B24+1 -> #REF! | G24: =SUMIF(#REF!,$B24,#REF!) -> #REF! | H24: =G24*$H$9 -> #REF! | I24: =SUM(G24:H24)*I$9 -> #REF! | J24: =SUM(G24:I24)*J$9 -> #REF! | K24: =SUM(G24:J24)*K$9 -> #REF! | L24: =SUM(G24:K24)*L$9 -> #REF! | M24: =SUM(G24:L24) -> #REF! | N24: =M24*N$9 -> #REF! | O24: =M24*O$9 -> #REF! | P24: =M24*P$9 -> #REF! | Q24: =SUM(N24:P24)*Q$9 -> #REF! | R24: =SUM(M24:Q24) -> #REF!
B25: =B24+1 -> #REF! | C25: =B25+1 -> #REF! | G25: =SUMIF(#REF!,$B25,#REF!) -> #REF! | H25: =G25*$H$9 -> #REF! | I25: =SUM(G25:H25)*I$9 -> #REF! | J25: =SUM(G25:I25)*J$9 -> #REF! | K25: =SUM(G25:J25)*K$9 -> #REF! | L25: =SUM(G25:K25)*L$9 -> #REF! | M25: =SUM(G25:L25) -> #REF! | N25: =M25*N$9 -> #REF! | O25: =M25*O$9 -> #REF! | P25: =M25*P$9 -> #REF! | Q25: =SUM(N25:P25)*Q$9 -> #REF! | R25: =SUM(M25:Q25) -> #REF!
B26: =B25+1 -> #REF! | C26: =B26+1 -> #REF! | G26: =SUMIF(#REF!,$B26,#REF!) -> #REF! | H26: =G26*$H$9 -> #REF! | I26: =SUM(G26:H26)*I$9 -> #REF! | J26: =SUM(G26:I26)*J$9 -> #REF! | K26: =SUM(G26:J26)*K$9 -> #REF! | L26: =SUM(G26:K26)*L$9 -> #REF! | M26: =SUM(G26:L26) -> #REF! | N26: =M26*N$9 -> #REF! | O26: =M26*O$9 -> #REF! | P26: =M26*P$9 -> #REF! | Q26: =SUM(N26:P26)*Q$9 -> #REF! | R26: =SUM(M26:Q26) -> #REF!
B27: =B26+1 -> #REF! | C27: =B27+1 -> #REF! | G27: =SUMIF(#REF!,$B27,#REF!) -> #REF! | H27: =G27*$H$9 -> #REF! | I27: =SUM(G27:H27)*I$9 -> #REF! | J27: =SUM(G27:I27)*J$9 -> #REF! | K27: =SUM(G27:J27)*K$9 -> #REF! | L27: =SUM(G27:K27)*L$9 -> #REF! | M27: =SUM(G27:L27) -> #REF! | N27: =M27*N$9 -> #REF! | O27: =M27*O$9 -> #REF! | P27: =M27*P$9 -> #REF! | Q27: =SUM(N27:P27)*Q$9 -> #REF! | R27: =SUM(M27:Q27) -> #REF!
... B61: =B60+1 -> #REF! | C61: =B61+1 -> #REF! | G61: =SUMIF(#REF!,$B61,#REF!) -> #REF! | H61: =G61*$H$9 -> #REF! | I61: =SUM(G61:H61)*I$9 -> #REF! | J61: =SUM(G61:I61)*J$9 -> #REF! | K61: =SUM(G61:J61)*K$9 -> #REF! | L61: =SUM(G61:K61)*L$9 -> #REF! | M61: =SUM(G61:L61) -> #REF! | N61: =M61*N$9 -> #REF! | O61: =M61*O$9 -> #REF! | P61: =M61*P$9 -> #REF! | Q61: =SUM(N61:P61)*Q$9 -> #REF! | R61: =SUM(M61:Q61) -> #REF!
H62: =G62*$H$9 -> 0 | I62: =SUM(G62:H62)*I$9 -> 0 | J62: =SUM(G62:I62)*J$9 -> 0 | K62: =SUM(G62:J62)*K$9 -> 0 | L62: =SUM(G62:K62)*L$9 -> 0 | M62: =SUM(G62:L62) -> 0 | N62: =M62*N$9 -> 0 | O62: =M62*O$9 -> 0 | P62: =M62*P$9 -> 0 | Q62: =SUM(N62:P62)*Q$9 -> 0 | R62: =SUM(M62:Q62) -> 0 | T62: =SUM(N62:Q62)*$S$69 -> 0 | U62: =M62*$S$69 -> 0 | V62: =(K62+L62+Q62)*S$69 -> 0
A64: Summary Water Distribution | G64: =SUM(G11:G62) -> #REF! | H64: =SUM(H11:H62) -> #REF! | I64: =SUM(I11:I62) -> #REF! | J64: =SUM(J11:J62) -> #REF! | K64: =SUM(K11:K62) -> #REF! | L64: =SUM(L11:L62) -> #REF! | M64: =SUM(M11:M62) -> #REF! | N64: =SUM(N11:N62) -> #REF! | ... R64: =SUM(R11:R62) -> #REF!

Sheet Richardson Water - R&R Proj
A1: Fort Richardson Water Distribution R&R Projects
A4: Project Number: Year 2
A5: Project Title: Upgrade Water System
A6: Year That Payment for Project Will Begin: Year 2 of the 50 Year Contract
A8: Project Description | B8: Year Implemented | C8: Year Payments Begin | D8: Quantity | E8: Unit of Measure | F8: Cost/UOM | G8: Base Constr Cost (no markups) | H8: Contingency | I8: Bonds, Insurance | J8: General Conditions | K8: G & A | L8: Profit | M8: Total Capital Cost | N8: Studies plus Predesign | O8: Design | P8: SDC | Q8: Fee on Professional Services | R8: Total Project Cost | T8: Engineering | U8: Construction | V8: GM
H9: 0.05 | I9: 0.02 | J9: 0.05 | K9: 0.122 | L9: 0.1 | N9: 0.077 | O9: 0.05 | P9: 0.03 | Q9: 0.1
A11: - | B11: =#REF! -> #REF! | C11: In Initial Replacements | G11: =SUMIF(#REF!,$B11,#REF!) -> #REF! | H11: =G11*$H$9 -> #REF! | I11: =SUM(G11:H11)*I$9 -> #REF! | J11: =SUM(G11:I11)*J$9 -> #REF! | K11: =SUM(G11:J11)*K$9 -> #REF! | L11: =SUM(G11:K11)*L$9 -> #REF! | M11: =SUM(G11:L11) -> #REF! | N11: =M11*N$9 -> #REF! | O11: =M11*O$9 -> #REF! | P11: =M11*P$9 -> #REF! | Q11: =SUM(N11:P11)*Q$9 -> #REF! | R11: =SUM(M11:Q11) -> #REF! | T11: =SUM(N11:Q11)*$S$69 -> #REF! | U11: =M11*$S$69 -> #REF! | V11: =(K11+L11+Q11)*S$69 -> #REF!
A12: - | B12: =B11+1 -> #REF! | C12: In Initial Replacements | G12: =SUMIF(#REF!,$B12,#REF!) -> #REF! | H12: =G12*$H$9 -> #REF! | I12: =SUM(G12:H12)*I$9 -> #REF! | J12: =SUM(G12:I12)*J$9 -> #REF! | K12: =SUM(G12:J12)*K$9 -> #REF! | L12: =SUM(G12:K12)*L$9 -> #REF! | M12: =SUM(G12:L12) -> #REF! | N12: =M12*N$9 -> #REF! | O12: =M12*O$9 -> #REF! | P12: =M12*P$9 -> #REF! | Q12: =SUM(N12:P12)*Q$9 -> #REF! | R12: =SUM(M12:Q12) -> #REF! | T12: =SUM(N12:Q12)*$S$69 -> #REF! | U12: =M12*$S$69 -> #REF! | V12: =(K12+L12+Q12)*S$69 -> #REF!
A13: - | B13: =B12+1 -> #REF! | C13: In Initial Replacements | G13: =SUMIF(#REF!,$B13,#REF!) -> #REF! | H13: =G13*$H$9 -> #REF! | I13: =SUM(G13:H13)*I$9 -> #REF! | J13: =SUM(G13:I13)*J$9 -> #REF! | K13: =SUM(G13:J13)*K$9 -> #REF! | L13: =SUM(G13:K13)*L$9 -> #REF! | M13: =SUM(G13:L13) -> #REF! | N13: =M13*N$9 -> #REF! | O13: =M13*O$9 -> #REF! | P13: =M13*P$9 -> #REF! | Q13: =SUM(N13:P13)*Q$9 -> #REF! | R13: =SUM(M13:Q13) -> #REF! | T13: =SUM(N13:Q13)*$S$69 -> #REF! | U13: =M13*$S$69 -> #REF! | V13: =(K13+L13+Q13)*S$69 -> #REF!
A14: - | B14: =B13+1 -> #REF! | C14: In Initial Replacements | G14: =SUMIF(#REF!,$B14,#REF!) -> #REF! | H14: =G14*$H$9 -> #REF! | I14: =SUM(G14:H14)*I$9 -> #REF! | J14: =SUM(G14:I14)*J$9 -> #REF! | K14: =SUM(G14:J14)*K$9 -> #REF! | L14: =SUM(G14:K14)*L$9 -> #REF! | M14: =SUM(G14:L14) -> #REF! | N14: =M14*N$9 -> #REF! | O14: =M14*O$9 -> #REF! | P14: =M14*P$9 -> #REF! | Q14: =SUM(N14:P14)*Q$9 -> #REF! | R14: =SUM(M14:Q14) -> #REF!
A15: - | B15: =B14+1 -> #REF! | C15: In Initial Replacements | G15: =SUMIF(#REF!,$B15,#REF!) -> #REF! | H15: =G15*$H$9 -> #REF! | I15: =SUM(G15:H15)*I$9 -> #REF! | J15: =SUM(G15:I15)*J$9 -> #REF! | K15: =SUM(G15:J15)*K$9 -> #REF! | L15: =SUM(G15:K15)*L$9 -> #REF! | M15: =SUM(G15:L15) -> #REF! | N15: =M15*N$9 -> #REF! | O15: =M15*O$9 -> #REF! | P15: =M15*P$9 -> #REF! | Q15: =SUM(N15:P15)*Q$9 -> #REF! | R15: =SUM(M15:Q15) -> #REF!
B16: =B15+1 -> #REF! | C16: =B16+1 -> #REF! | G16: =SUMIF(#REF!,$B16,#REF!) -> #REF! | H16: =G16*$H$9 -> #REF! | I16: =SUM(G16:H16)*I$9 -> #REF! | J16: =SUM(G16:I16)*J$9 -> #REF! | K16: =SUM(G16:J16)*K$9 -> #REF! | L16: =SUM(G16:K16)*L$9 -> #REF! | M16: =SUM(G16:L16) -> #REF! | N16: =M16*N$9 -> #REF! | O16: =M16*O$9 -> #REF! | P16: =M16*P$9 -> #REF! | Q16: =SUM(N16:P16)*Q$9 -> #REF! | R16: =SUM(M16:Q16) -> #REF!
B17: =B16+1 -> #REF! | C17: =B17+1 -> #REF! | G17: =SUMIF(#REF!,$B17,#REF!) -> #REF! | H17: =G17*$H$9 -> #REF! | I17: =SUM(G17:H17)*I$9 -> #REF! | J17: =SUM(G17:I17)*J$9 -> #REF! | K17: =SUM(G17:J17)*K$9 -> #REF! | L17: =SUM(G17:K17)*L$9 -> #REF! | M17: =SUM(G17:L17) -> #REF! | N17: =M17*N$9 -> #REF! | O17: =M17*O$9 -> #REF! | P17: =M17*P$9 -> #REF! | Q17: =SUM(N17:P17)*Q$9 -> #REF! | R17: =SUM(M17:Q17) -> #REF!
B18: =B17+1 -> #REF! | C18: =B18+1 -> #REF! | G18: =SUMIF(#REF!,$B18,#REF!) -> #REF! | H18: =G18*$H$9 -> #REF! | I18: =SUM(G18:H18)*I$9 -> #REF! | J18: =SUM(G18:I18)*J$9 -> #REF! | K18: =SUM(G18:J18)*K$9 -> #REF! | L18: =SUM(G18:K18)*L$9 -> #REF! | M18: =SUM(G18:L18) -> #REF! | N18: =M18*N$9 -> #REF! | O18: =M18*O$9 -> #REF! | P18: =M18*P$9 -> #REF! | Q18: =SUM(N18:P18)*Q$9 -> #REF! | R18: =SUM(M18:Q18) -> #REF!
B19: =B18+1 -> #REF! | C19: =B19+1 -> #REF! | G19: =SUMIF(#REF!,$B19,#REF!) -> #REF! | H19: =G19*$H$9 -> #REF! | I19: =SUM(G19:H19)*I$9 -> #REF! | J19: =SUM(G19:I19)*J$9 -> #REF! | K19: =SUM(G19:J19)*K$9 -> #REF! | L19: =SUM(G19:K19)*L$9 -> #REF! | M19: =SUM(G19:L19) -> #REF! | N19: =M19*N$9 -> #REF! | O19: =M19*O$9 -> #REF! | P19: =M19*P$9 -> #REF! | Q19: =SUM(N19:P19)*Q$9 -> #REF! | R19: =SUM(M19:Q19) -> #REF!
B20: =B19+1 -> #REF! | C20: =B20+1 -> #REF! | G20: =SUMIF(#REF!,$B20,#REF!) -> #REF! | H20: =G20*$H$9 -> #REF! | I20: =SUM(G20:H20)*I$9 -> #REF! | J20: =SUM(G20:I20)*J$9 -> #REF! | K20: =SUM(G20:J20)*K$9 -> #REF! | L20: =SUM(G20:K20)*L$9 -> #REF! | M20: =SUM(G20:L20) -> #REF! | N20: =M20*N$9 -> #REF! | O20: =M20*O$9 -> #REF! | P20: =M20*P$9 -> #REF! | Q20: =SUM(N20:P20)*Q$9 -> #REF! | R20: =SUM(M20:Q20) -> #REF!
B21: =B20+1 -> #REF! | C21: =B21+1 -> #REF! | G21: =SUMIF(#REF!,$B21,#REF!) -> #REF! | H21: =G21*$H$9 -> #REF! | I21: =SUM(G21:H21)*I$9 -> #REF! | J21: =SUM(G21:I21)*J$9 -> #REF! | K21: =SUM(G21:J21)*K$9 -> #REF! | L21: =SUM(G21:K21)*L$9 -> #REF! | M21: =SUM(G21:L21) -> #REF! | N21: =M21*N$9 -> #REF! | O21: =M21*O$9 -> #REF! | P21: =M21*P$9 -> #REF! | Q21: =SUM(N21:P21)*Q$9 -> #REF! | R21: =SUM(M21:Q21) -> #REF!
B22: =B21+1 -> #REF! | C22: =B22+1 -> #REF! | G22: =SUMIF(#REF!,$B22,#REF!) -> #REF! | H22: =G22*$H$9 -> #REF! | I22: =SUM(G22:H22)*I$9 -> #REF! | J22: =SUM(G22:I22)*J$9 -> #REF! | K22: =SUM(G22:J22)*K$9 -> #REF! | L22: =SUM(G22:K22)*L$9 -> #REF! | M22: =SUM(G22:L22) -> #REF! | N22: =M22*N$9 -> #REF! | O22: =M22*O$9 -> #REF! | P22: =M22*P$9 -> #REF! | Q22: =SUM(N22:P22)*Q$9 -> #REF! | R22: =SUM(M22:Q22) -> #REF!
B23: =B22+1 -> #REF! | C23: =B23+1 -> #REF! | G23: =SUMIF(#REF!,$B23,#REF!) -> #REF! | H23: =G23*$H$9 -> #REF! | I23: =SUM(G23:H23)*I$9 -> #REF! | J23: =SUM(G23:I23)*J$9 -> #REF! | K23: =SUM(G23:J23)*K$9 -> #REF! | L23: =SUM(G23:K23)*L$9 -> #REF! | M23: =SUM(G23:L23) -> #REF! | N23: =M23*N$9 -> #REF! | O23: =M23*O$9 -> #REF! | P23: =M23*P$9 -> #REF! | Q23: =SUM(N23:P23)*Q$9 -> #REF! | R23: =SUM(M23:Q23) -> #REF!
B24: =B23+1 -> #REF! | C24: =B24+1 -> #REF! | G24: =SUMIF(#REF!,$B24,#REF!) -> #REF! | H24: =G24*$H$9 -> #REF! | I24: =SUM(G24:H24)*I$9 -> #REF! | J24: =SUM(G24:I24)*J$9 -> #REF! | K24: =SUM(G24:J24)*K$9 -> #REF! | L24: =SUM(G24:K24)*L$9 -> #REF! | M24: =SUM(G24:L24) -> #REF! | N24: =M24*N$9 -> #REF! | O24: =M24*O$9 -> #REF! | P24: =M24*P$9 -> #REF! | Q24: =SUM(N24:P24)*Q$9 -> #REF! | R24: =SUM(M24:Q24) -> #REF!
B25: =B24+1 -> #REF! | C25: =B25+1 -> #REF! | G25: =SUMIF(#REF!,$B25,#REF!) -> #REF! | H25: =G25*$H$9 -> #REF! | I25: =SUM(G25:H25)*I$9 -> #REF! | J25: =SUM(G25:I25)*J$9 -> #REF! | K25: =SUM(G25:J25)*K$9 -> #REF! | L25: =SUM(G25:K25)*L$9 -> #REF! | M25: =SUM(G25:L25) -> #REF! | N25: =M25*N$9 -> #REF! | O25: =M25*O$9 -> #REF! | P25: =M25*P$9 -> #REF! | Q25: =SUM(N25:P25)*Q$9 -> #REF! | R25: =SUM(M25:Q25) -> #REF!
B26: =B25+1 -> #REF! | C26: =B26+1 -> #REF! | G26: =SUMIF(#REF!,$B26,#REF!) -> #REF! | H26: =G26*$H$9 -> #REF! | I26: =SUM(G26:H26)*I$9 -> #REF! | J26: =SUM(G26:I26)*J$9 -> #REF! | K26: =SUM(G26:J26)*K$9 -> #REF! | L26: =SUM(G26:K26)*L$9 -> #REF! | M26: =SUM(G26:L26) -> #REF! | N26: =M26*N$9 -> #REF! | O26: =M26*O$9 -> #REF! | P26: =M26*P$9 -> #REF! | Q26: =SUM(N26:P26)*Q$9 -> #REF! | R26: =SUM(M26:Q26) -> #REF!
B27: =B26+1 -> #REF! | C27: =B27+1 -> #REF! | G27: =SUMIF(#REF!,$B27,#REF!) -> #REF! | H27: =G27*$H$9 -> #REF! | I27: =SUM(G27:H27)*I$9 -> #REF! | J27: =SUM(G27:I27)*J$9 -> #REF! | K27: =SUM(G27:J27)*K$9 -> #REF! | L27: =SUM(G27:K27)*L$9 -> #REF! | M27: =SUM(G27:L27) -> #REF! | N27: =M27*N$9 -> #REF! | O27: =M27*O$9 -> #REF! | P27: =M27*P$9 -> #REF! | Q27: =SUM(N27:P27)*Q$9 -> #REF! | R27: =SUM(M27:Q27) -> #REF!
... B61: =B60+1 -> #REF! | C61: =B61+1 -> #REF! | G61: =SUMIF(#REF!,$B61,#REF!) -> #REF! | H61: =G61*$H$9 -> #REF! | I61: =SUM(G61:H61)*I$9 -> #REF! | J61: =SUM(G61:I61)*J$9 -> #REF! | K61: =SUM(G61:J61)*K$9 -> #REF! | L61: =SUM(G61:K61)*L$9 -> #REF! | M61: =SUM(G61:L61) -> #REF! | N61: =M61*N$9 -> #REF! | O61: =M61*O$9 -> #REF! | P61: =M61*P$9 -> #REF! | Q61: =SUM(N61:P61)*Q$9 -> #REF! | R61: =SUM(M61:Q61) -> #REF!
H62: =G62*$H$9 -> 0 | I62: =SUM(G62:H62)*I$9 -> 0 | J62: =SUM(G62:I62)*J$9 -> 0 | K62: =SUM(G62:J62)*K$9 -> 0 | L62: =SUM(G62:K62)*L$9 -> 0 | M62: =SUM(G62:L62) -> 0 | N62: =M62*N$9 -> 0 | O62: =M62*O$9 -> 0 | P62: =M62*P$9 -> 0 | Q62: =SUM(N62:P62)*Q$9 -> 0 | R62: =SUM(M62:Q62) -> 0 | T62: =SUM(N62:Q62)*$S$69 -> 0 | U62: =M62*$S$69 -> 0 | V62: =(K62+L62+Q62)*S$69 -> 0
A64: Summary Water Distribution | G64: =SUM(G11:G62) -> #REF! | H64: =SUM(H11:H62) -> #REF! | I64: =SUM(I11:I62) -> #REF! | J64: =SUM(J11:J62) -> #REF! | K64: =SUM(K11:K62) -> #REF! | L64: =SUM(L11:L62) -> #REF! | M64: =SUM(M11:M62) -> #REF! | N64: =SUM(N11:N62) -> #REF! | ... R64: =SUM(R11:R62) -> #REF!

Sheet Wainwright Summary
B2: Doyon Utilities, LLC
B3: Fort Wainwright Utility Inventory and Replacement Cost
B4: Fort Wainwright Summary
A6: Estimate Basis Year | E6: 2007
A7: Year of Implementation | E7: 2008
A9: Note: RCN INCLUDES Contractor Mark-ups and Studies/Enginering Costs to 2058 only | B9: CIP Projects and initial R&R Projects (RCN w. mark-ups and engineering Costs) - from CIP workbook - | C9: RCN (Total w. Enginering) Yrs 6-10 | D9: Capital Investment Yrs 1-10 | E9: RCN (Total w. Enginering) Yrs 11-50 | F9: Total 50 year Capex | G9: RCNLD (Kind-for-Kind) | H9: RCNLD (PDC Harris estimate for 30 Mwe CFB plant | I9: Appraisal Valueation (Capitalized earnings) | J9: OC | K9: OCLD | M9: Purchase Offer | N9: Valuation basis | O9: Average Depreciation Years remaining
B10: 2009-2013 | C10: 2014-2018 only
A11: Wainwright CHPP only | B11: ='CM Cost Estimating Worksheet'!#REF! -> #REF! | C11: ='CM Cost Estimating Worksheet'!#REF! -> #REF! | D11: =SUM(B11:C11) -> #REF! | E11: ='CM Cost Estimating Worksheet'!#REF! -> #REF! | F11: =SUM(D11:E11) -> #REF! | G11: ='CM Cost Estimating Worksheet'!#REF! -> #REF! | H11: =107000000*0.17 -> 18190000 | J11: ='CM Cost Estimating Worksheet'!#REF! -> #REF! | K11: ='CM Cost Estimating Worksheet'!#REF! -> #REF! | M11: =K11 -> #REF! | N11: OCLD | O11: ='CM Cost Estimating Worksheet'!#REF!-2008 -> #REF!
A12: Wainwright Heat Distribution only | B12: ='CM Cost Estimating Worksheet'!#REF! -> #REF! | C12: ='CM Cost Estimating Worksheet'!#REF! -> #REF! | D12: =SUM(B12:C12) -> #REF! | E12: ='CM Cost Estimating Worksheet'!#REF! -> #REF! | F12: =SUM(D12:E12) -> #REF! | G12: ='CM Cost Estimating Worksheet'!#REF! -> #REF! | H12: na | J12: ='CM Cost Estimating Worksheet'!#REF! -> #REF! | K12: ='CM Cost Estimating Worksheet'!#REF! -> #REF! | M12: =ROUND(K12,-2) -> #REF! | N12: OCLD | O12: ='CM Cost Estimating Worksheet'!#REF!-2008 -> #REF!
A13: Wainwright Utilidors | B13: ='CM Cost Estimating Worksheet'!#REF! -> #REF! | C13: ='CM Cost Estimating Worksheet'!#REF! -> #REF! | D13: =SUM(B13:C13) -> #REF! | E13: ='CM Cost Estimating Worksheet'!AA11 -> 0 | F13: =SUM(D13:E13) -> #REF! | G13: ='CM Cost Estimating Worksheet'!#REF! -> #REF! | H13: na | J13: ='CM Cost Estimating Worksheet'!#REF! -> #REF! | K13: ='CM Cost Estimating Worksheet'!#REF! -> #REF! | M13: =K13 -> #REF! | N13: OCLD | O13: ='CM Cost Estimating Worksheet'!#REF!-2008 -> #REF!
A14: Total CHP&P & HDS | B14: =SUM(B11:B13) -> #REF! | C14: =SUM(C11:C13) -> #REF! | D14: =SUM(D11:D13) -> #REF! | E14: =SUM(E11:E13) -> #REF! | F14: =SUM(F11:F13) -> #REF! | G14: =SUM(G11:G13) -> #REF! | H14: =SUM(H11:H13) -> 18190000 | I14: 37700000 | J14: =SUM(J11:J13) -> #REF! | K14: =SUM(K11:K13) -> #REF! | M14: =SUM(M11:M13) -> #REF! | O14: =AVERAGE(O12,O11) -> #REF!
A16: Wainwright Electrical Distribution | B16: ='Wainwright Electrical Dist'!AA168 -> 33925662 | C16: ='Wainwright Electrical Dist'!AA169 -> 2704087.7 | D16: =SUM(B16:C16) -> 36629749 | E16: ='Wainwright Electrical Dist'!AA170 -> 18795289 | F16: =SUM(D16:E16) -> 55425038 | G16: ='Wainwright Electrical Dist'!AC167 -> 14411691 | J16: ='Wainwright Electrical Dist'!AE167 -> 16384700 | K16: ='Wainwright Electrical Dist'!AF167 -> 4605102.6 | M16: =ROUND(K16,-2) -> 4605100 | N16: OCLD | O16: ='Wainwright Electrical Dist'!AG171-2008 -> 16.857021
A18: Wainwright Water Distribution | B18: ='Wainwright Water Dist'!AA247 -> 3425005.9 | C18: ='Wainwright Water Dist'!AA248 -> 101990 | D18: =SUM(B18:C18) -> 3526995.9 | E18: ='Wainwright Water Dist'!AA249 -> 47424079 | F18: =SUM(D18:E18) -> 50951075 | G18: ='Wainwright Water Dist'!AC246 -> 23031903 | J18: ='Wainwright Water Dist'!AE246 -> 17786031 | K18: ='Wainwright Water Dist'!AF246 -> 7746729.1 | M18: =ROUND(K18,-2) -> 7746700 | N18: OCLD | O18: ='Wainwright Water Dist'!AG252-2008 -> 19.184938
A20: Wainwright Wastewater Collection | B20: ='Wainwright WW Collection'!AA340 -> 9637438.7 | C20: ='Wainwright WW Collection'!AA341 -> 1049081.4 | D20: =SUM(B20:C20) -> 10686520 | E20: ='Wainwright WW Collection'!AA342 -> 33873420 | F20: =SUM(D20:E20) -> 44559940 | G20: ='Wainwright WW Collection'!AC335 -> 19164563 | J20: ='Wainwright WW Collection'!AE335 -> 9820568.3 | K20: ='Wainwright WW Collection'!AF335 -> 4420127.9 | M20: =ROUND(K20,-2) -> 4420100 | N20: OCLD | O20: ='Wainwright WW Collection'!AG343-2008 -> 29.2
A22: Total | B22: =SUM(B14:B20) -> #REF! | C22: =SUM(C14:C20) -> #REF! | D22: =SUM(D14:D20) -> #REF! | E22: =SUM(E14:E20) -> #REF! | F22: =SUM(F14:F20) -> #REF! | G22: =SUM(G11:G21) -> #REF! | J22: =SUM(J14:J20) -> #REF! | K22: =SUM(K14:K20) -> #REF! | M22: =SUM(M14:M21) -> #REF!
B24: C/S (20% min) | C24: 0.35 | D24: =$C$24*D22 -> #REF! | E24: =$C$24*E22 -> #REF! | F24: =$C$24*F22 -> #REF! | M24: financed by amortization of Purchase debt
B25: Sub-Debt | C25: 0 | D25: =D22*$C$25 -> #REF! | E25: =E22*$C$25 -> #REF! | F25: =F22*$C$25 -> #REF! | M25: by internal Depreciation charges (cashflow neurtal)
B26: Senior Debt | C26: =1-C24-C25 -> 0.65 | D26: =D22-D24-D25 -> #REF! | E26: =E22-E24-E25 -> #REF! | F26: =F22-F24-F25 -> #REF!
B27: (Investment Grade) | C27: =SUM(C24:C26) -> 1 | D27: =SUM(D24:D26) -> #REF! | E27: =SUM(E24:E26) -> #REF! | F27: =SUM(F24:F26) -> #REF!
B29: DOYON Equity | C29: 0.51 | D29: =D24*$C$29 -> #REF! | E29: =E24*$C$29 -> #REF! | F29: =F24*$C$29 -> #REF!
B30: FSW Equity | C30: 0.245 | D30: =D24*$C$30 -> #REF! | E30: =E24*$C$30 -> #REF! | F30: =F24*$C$30 -> #REF!
B31: AES Equity | C31: 0.245 | D31: =D24*$C$31 -> #REF! | E31: =E24*$C$31 -> #REF! | F31: =F24*$C$31 -> #REF!
D32: =SUM(D29:D31) -> #REF! | E32: =SUM(E29:E31) -> #REF! | F32: =SUM(F29:F31) -> #REF!
A34: Debt Financed (60%) | B34: =0.6*B22 -> #REF! | C34: =0.6*C22 -> #REF! | D34: =0.6*D22 -> #REF! | E34: =0.6*E22 -> #REF! | F34: =0.6*F22 -> #REF! | M34: Contrbution in Add of Construction Tax:
A35: Equity Financed (40%) | B35: =0.4*B22 -> #REF! | C35: =0.4*C22 -> #REF! | D35: =0.4*D22 -> #REF! | E35: =0.4*E22 -> #REF! | F35: =0.4*F22 -> #REF! | M35: Purchase Price: | N35: =M11 -> #REF! | O35: =N11 -> OCLD
M36: Appraisal Value: | N36: =I14 -> 37700000 | O36: earnings mulytiple
M37: RCNLD (CFB Boiler): | N37: =H14 -> 18190000 | O37: RCNLD (new tech)
M39: Purchase price is based on RCA standard methodology for regulated
M40: utilities based on OCLD. CIAC Tax is not applicable on power & HDS
M41: assets ifthe Proposed purchase price is in excess of FMV or other valuation
M42: methods.

Sheet Wainwright CHPP&Dist- R&R Proj
A1: Fort Wainwright CHPP and Heat Distribution R&R Projects
A4: Project Number: Year 2
A5: Project Title: Upgrade Water System
A6: Year That Payment for Project Will Begin: Year 2 of the 50 Year Contract
A8: Project Description | B8: Year Implemented | C8: Year Payments Begin | D8: Quantity | E8: Unit of Measure | F8: Cost/UOM | G8: Base Constr Cost (no markups) | H8: Contingency | I8: Bonds, Insurance | J8: General Conditions | K8: G & A | L8: Profit | M8: Total Capital Cost | N8: Studies plus Predesign | O8: Design | P8: SDC | Q8: Fee on Professional Services | R8: Total Project Cost | T8: Engineering | U8: Construction | V8: GM
H9: 0.05 | I9: 0.02 | J9: 0.05 | K9: 0.122 | L9: 0.1 | N9: 0.077 | O9: 0.05 | P9: 0.03 | Q9: 0.1
A11: - | B11: ='Wainwright Summary'!E7 -> 2008 | C11: In Initial Replacements | G11: =SUMIF(Wainwright_All_R_R_Th!$D$4:$BB$4,$B11,Wainwright_All_R_R_Th!$D$5:$BB$5) -> 0 | H11: =G11*$H$9 -> 0 | I11: =SUM(G11:H11)*I$9 -> 0 | J11: =SUM(G11:I11)*J$9 -> 0 | K11: =SUM(G11:J11)*K$9 -> 0 | L11: =SUM(G11:K11)*L$9 -> 0 | M11: =SUM(G11:L11) -> 0 | N11: =M11*N$9 -> 0 | O11: =M11*O$9 -> 0 | P11: =M11*P$9 -> 0 | Q11: =SUM(N11:P11)*Q$9 -> 0 | R11: =SUM(M11:Q11) -> 0 | T11: =SUM(N11:Q11)*$S$69 -> 0 | U11: =M11*$S$69 -> 0 | V11: =(K11+L11+Q11)*S$69 -> 0
A12: - | B12: =B11+1 -> 2009 | C12: In Initial Replacements | G12: =SUMIF(Wainwright_All_R_R_Th!$D$4:$BB$4,$B12,Wainwright_All_R_R_Th!$D$5:$BB$5) -> 12350 | H12: =G12*$H$9 -> 617.5 | I12: =SUM(G12:H12)*I$9 -> 259.35 | J12: =SUM(G12:I12)*J$9 -> 661.3425 | K12: =SUM(G12:J12)*K$9 -> 1694.3595 | L12: =SUM(G12:K12)*L$9 -> 1558.2552 | M12: =SUM(G12:L12) -> 17140.807 | N12: =M12*N$9 -> 1319.8422 | O12: =M12*O$9 -> 857.04036 | P12: =M12*P$9 -> 514.22422 | Q12: =SUM(N12:P12)*Q$9 -> 269.11067 | R12: =SUM(M12:Q12) -> 20101.025 | T12: =SUM(N12:Q12)*$S$69 -> 0 | U12: =M12*$S$69 -> 0 | V12: =(K12+L12+Q12)*S$69 -> 0
A13: - | B13: =B12+1 -> 2010 | C13: In Initial Replacements | G13: =SUMIF(Wainwright_All_R_R_Th!$D$4:$BB$4,$B13,Wainwright_All_R_R_Th!$D$5:$BB$5) -> 0 | H13: =G13*$H$9 -> 0 | I13: =SUM(G13:H13)*I$9 -> 0 | J13: =SUM(G13:I13)*J$9 -> 0 | K13: =SUM(G13:J13)*K$9 -> 0 | L13: =SUM(G13:K13)*L$9 -> 0 | M13: =SUM(G13:L13) -> 0 | N13: =M13*N$9 -> 0 | O13: =M13*O$9 -> 0 | P13: =M13*P$9 -> 0 | Q13: =SUM(N13:P13)*Q$9 -> 0 | R13: =SUM(M13:Q13) -> 0 | T13: =SUM(N13:Q13)*$S$69 -> 0 | U13: =M13*$S$69 -> 0 | V13: =(K13+L13+Q13)*S$69 -> 0
A14: - | B14: =B13+1 -> 2011 | C14: In Initial Replacements | G14: =SUMIF(Wainwright_All_R_R_Th!$D$4:$BB$4,$B14,Wainwright_All_R_R_Th!$D$5:$BB$5) -> 0 | H14: =G14*$H$9 -> 0 | I14: =SUM(G14:H14)*I$9 -> 0 | J14: =SUM(G14:I14)*J$9 -> 0 | K14: =SUM(G14:J14)*K$9 -> 0 | L14: =SUM(G14:K14)*L$9 -> 0 | M14: =SUM(G14:L14) -> 0 | N14: =M14*N$9 -> 0 | O14: =M14*O$9 -> 0 | P14: =M14*P$9 -> 0 | Q14: =SUM(N14:P14)*Q$9 -> 0 | R14: =SUM(M14:Q14) -> 0
A15: - | B15: =B14+1 -> 2012 | C15: In Initial Replacements | G15: =SUMIF(Wainwright_All_R_R_Th!$D$4:$BB$4,$B15,Wainwright_All_R_R_Th!$D$5:$BB$5) -> 0 | H15: =G15*$H$9 -> 0 | I15: =SUM(G15:H15)*I$9 -> 0 | J15: =SUM(G15:I15)*J$9 -> 0 | K15: =SUM(G15:J15)*K$9 -> 0 | L15: =SUM(G15:K15)*L$9 -> 0 | M15: =SUM(G15:L15) -> 0 | N15: =M15*N$9 -> 0 | O15: =M15*O$9 -> 0 | P15: =M15*P$9 -> 0 | Q15: =SUM(N15:P15)*Q$9 -> 0 | R15: =SUM(M15:Q15) -> 0
B16: =B15+1 -> 2013 | C16: =B16+1 -> 2014 | G16: =SUMIF(Wainwright_All_R_R_Th!$D$4:$BB$4,$B16,Wainwright_All_R_R_Th!$D$5:$BB$5) -> 0 | H16: =G16*$H$9 -> 0 | I16: =SUM(G16:H16)*I$9 -> 0 | J16: =SUM(G16:I16)*J$9 -> 0 | K16: =SUM(G16:J16)*K$9 -> 0 | L16: =SUM(G16:K16)*L$9 -> 0 | M16: =SUM(G16:L16) -> 0 | N16: =M16*N$9 -> 0 | O16: =M16*O$9 -> 0 | P16: =M16*P$9 -> 0 | Q16: =SUM(N16:P16)*Q$9 -> 0 | R16: =SUM(M16:Q16) -> 0
B17: =B16+1 -> 2014 | C17: =B17+1 -> 2015 | G17: =SUMIF(Wainwright_All_R_R_Th!$D$4:$BB$4,$B17,Wainwright_All_R_R_Th!$D$5:$BB$5) -> 0 | H17: =G17*$H$9 -> 0 | I17: =SUM(G17:H17)*I$9 -> 0 | J17: =SUM(G17:I17)*J$9 -> 0 | K17: =SUM(G17:J17)*K$9 -> 0 | L17: =SUM(G17:K17)*L$9 -> 0 | M17: =SUM(G17:L17) -> 0 | N17: =M17*N$9 -> 0 | O17: =M17*O$9 -> 0 | P17: =M17*P$9 -> 0 | Q17: =SUM(N17:P17)*Q$9 -> 0 | R17: =SUM(M17:Q17) -> 0
B18: =B17+1 -> 2015 | C18: =B18+1 -> 2016 | G18: =SUMIF(Wainwright_All_R_R_Th!$D$4:$BB$4,$B18,Wainwright_All_R_R_Th!$D$5:$BB$5) -> 0 | H18: =G18*$H$9 -> 0 | I18: =SUM(G18:H18)*I$9 -> 0 | J18: =SUM(G18:I18)*J$9 -> 0 | K18: =SUM(G18:J18)*K$9 -> 0 | L18: =SUM(G18:K18)*L$9 -> 0 | M18: =SUM(G18:L18) -> 0 | N18: =M18*N$9 -> 0 | O18: =M18*O$9 -> 0 | P18: =M18*P$9 -> 0 | Q18: =SUM(N18:P18)*Q$9 -> 0 | R18: =SUM(M18:Q18) -> 0
B19: =B18+1 -> 2016 | C19: =B19+1 -> 2017 | G19: =SUMIF(Wainwright_All_R_R_Th!$D$4:$BB$4,$B19,Wainwright_All_R_R_Th!$D$5:$BB$5) -> 0 | H19: =G19*$H$9 -> 0 | I19: =SUM(G19:H19)*I$9 -> 0 | J19: =SUM(G19:I19)*J$9 -> 0 | K19: =SUM(G19:J19)*K$9 -> 0 | L19: =SUM(G19:K19)*L$9 -> 0 | M19: =SUM(G19:L19) -> 0 | N19: =M19*N$9 -> 0 | O19: =M19*O$9 -> 0 | P19: =M19*P$9 -> 0 | Q19: =SUM(N19:P19)*Q$9 -> 0 | R19: =SUM(M19:Q19) -> 0
B20: =B19+1 -> 2017 | C20: =B20+1 -> 2018 | G20: =SUMIF(Wainwright_All_R_R_Th!$D$4:$BB$4,$B20,Wainwright_All_R_R_Th!$D$5:$BB$5) -> 0 | H20: =G20*$H$9 -> 0 | I20: =SUM(G20:H20)*I$9 -> 0 | J20: =SUM(G20:I20)*J$9 -> 0 | K20: =SUM(G20:J20)*K$9 -> 0 | L20: =SUM(G20:K20)*L$9 -> 0 | M20: =SUM(G20:L20) -> 0 | N20: =M20*N$9 -> 0 | O20: =M20*O$9 -> 0 | P20: =M20*P$9 -> 0 | Q20: =SUM(N20:P20)*Q$9 -> 0 | R20: =SUM(M20:Q20) -> 0
B21: =B20+1 -> 2018 | C21: =B21+1 -> 2019 | G21: =SUMIF(Wainwright_All_R_R_Th!$D$4:$BB$4,$B21,Wainwright_All_R_R_Th!$D$5:$BB$5) -> 0 | H21: =G21*$H$9 -> 0 | I21: =SUM(G21:H21)*I$9 -> 0 | J21: =SUM(G21:I21)*J$9 -> 0 | K21: =SUM(G21:J21)*K$9 -> 0 | L21: =SUM(G21:K21)*L$9 -> 0 | M21: =SUM(G21:L21) -> 0 | N21: =M21*N$9 -> 0 | O21: =M21*O$9 -> 0 | P21: =M21*P$9 -> 0 | Q21: =SUM(N21:P21)*Q$9 -> 0 | R21: =SUM(M21:Q21) -> 0
B22: =B21+1 -> 2019 | C22: =B22+1 -> 2020 | G22: =SUMIF(Wainwright_All_R_R_Th!$D$4:$BB$4,$B22,Wainwright_All_R_R_Th!$D$5:$BB$5) -> 0 | H22: =G22*$H$9 -> 0 | I22: =SUM(G22:H22)*I$9 -> 0 | J22: =SUM(G22:I22)*J$9 -> 0 | K22: =SUM(G22:J22)*K$9 -> 0 | L22: =SUM(G22:K22)*L$9 -> 0 | M22: =SUM(G22:L22) -> 0 | N22: =M22*N$9 -> 0 | O22: =M22*O$9 -> 0 | P22: =M22*P$9 -> 0 | Q22: =SUM(N22:P22)*Q$9 -> 0 | R22: =SUM(M22:Q22) -> 0
B23: =B22+1 -> 2020 | C23: =B23+1 -> 2021 | G23: =SUMIF(Wainwright_All_R_R_Th!$D$4:$BB$4,$B23,Wainwright_All_R_R_Th!$D$5:$BB$5) -> 0 | H23: =G23*$H$9 -> 0 | I23: =SUM(G23:H23)*I$9 -> 0 | J23: =SUM(G23:I23)*J$9 -> 0 | K23: =SUM(G23:J23)*K$9 -> 0 | L23: =SUM(G23:K23)*L$9 -> 0 | M23: =SUM(G23:L23) -> 0 | N23: =M23*N$9 -> 0 | O23: =M23*O$9 -> 0 | P23: =M23*P$9 -> 0 | Q23: =SUM(N23:P23)*Q$9 -> 0 | R23: =SUM(M23:Q23) -> 0
B24: =B23+1 -> 2021 | C24: =B24+1 -> 2022 | G24: =SUMIF(Wainwright_All_R_R_Th!$D$4:$BB$4,$B24,Wainwright_All_R_R_Th!$D$5:$BB$5) -> 0 | H24: =G24*$H$9 -> 0 | I24: =SUM(G24:H24)*I$9 -> 0 | J24: =SUM(G24:I24)*J$9 -> 0 | K24: =SUM(G24:J24)*K$9 -> 0 | L24: =SUM(G24:K24)*L$9 -> 0 | M24: =SUM(G24:L24) -> 0 | N24: =M24*N$9 -> 0 | O24: =M24*O$9 -> 0 | P24: =M24*P$9 -> 0 | Q24: =SUM(N24:P24)*Q$9 -> 0 | R24: =SUM(M24:Q24) -> 0
B25: =B24+1 -> 2022 | C25: =B25+1 -> 2023 | G25: =SUMIF(Wainwright_All_R_R_Th!$D$4:$BB$4,$B25,Wainwright_All_R_R_Th!$D$5:$BB$5) -> 0 | H25: =G25*$H$9 -> 0 | I25: =SUM(G25:H25)*I$9 -> 0 | J25: =SUM(G25:I25)*J$9 -> 0 | K25: =SUM(G25:J25)*K$9 -> 0 | L25: =SUM(G25:K25)*L$9 -> 0 | M25: =SUM(G25:L25) -> 0 | N25: =M25*N$9 -> 0 | O25: =M25*O$9 -> 0 | P25: =M25*P$9 -> 0 | Q25: =SUM(N25:P25)*Q$9 -> 0 | R25: =SUM(M25:Q25) -> 0
B26: =B25+1 -> 2023 | C26: =B26+1 -> 2024 | G26: =SUMIF(Wainwright_All_R_R_Th!$D$4:$BB$4,$B26,Wainwright_All_R_R_Th!$D$5:$BB$5) -> 0 | H26: =G26*$H$9 -> 0 | I26: =SUM(G26:H26)*I$9 -> 0 | J26: =SUM(G26:I26)*J$9 -> 0 | K26: =SUM(G26:J26)*K$9 -> 0 | L26: =SUM(G26:K26)*L$9 -> 0 | M26: =SUM(G26:L26) -> 0 | N26: =M26*N$9 -> 0 | O26: =M26*O$9 -> 0 | P26: =M26*P$9 -> 0 | Q26: =SUM(N26:P26)*Q$9 -> 0 | R26: =SUM(M26:Q26) -> 0
B27: =B26+1 -> 2024 | C27: =B27+1 -> 2025 | G27: =SUMIF(Wainwright_All_R_R_Th!$D$4:$BB$4,$B27,Wainwright_All_R_R_Th!$D$5:$BB$5) -> 0 | H27: =G27*$H$9 -> 0 | I27: =SUM(G27:H27)*I$9 -> 0 | J27: =SUM(G27:I27)*J$9 -> 0 | K27: =SUM(G27:J27)*K$9 -> 0 | L27: =SUM(G27:K27)*L$9 -> 0 | M27: =SUM(G27:L27) -> 0 | N27: =M27*N$9 -> 0 | O27: =M27*O$9 -> 0 | P27: =M27*P$9 -> 0 | Q27: =SUM(N27:P27)*Q$9 -> 0 | R27: =SUM(M27:Q27) -> 0
... B61: =B60+1 -> 2058 | C61: =B61+1 -> 2059 | G61: =SUMIF(Wainwright_All_R_R_Th!$D$4:$BB$4,$B61,Wainwright_All_R_R_Th!$D$5:$BB$5) -> 0 | H61: =G61*$H$9 -> 0 | I61: =SUM(G61:H61)*I$9 -> 0 | J61: =SUM(G61:I61)*J$9 -> 0 | K61: =SUM(G61:J61)*K$9 -> 0 | L61: =SUM(G61:K61)*L$9 -> 0 | M61: =SUM(G61:L61) -> 0 | N61: =M61*N$9 -> 0 | O61: =M61*O$9 -> 0 | P61: =M61*P$9 -> 0 | Q61: =SUM(N61:P61)*Q$9 -> 0 | R61: =SUM(M61:Q61) -> 0
H62: =G62*$H$9 -> 0 | I62: =SUM(G62:H62)*I$9 -> 0 | J62: =SUM(G62:I62)*J$9 -> 0 | K62: =SUM(G62:J62)*K$9 -> 0 | L62: =SUM(G62:K62)*L$9 -> 0 | M62: =SUM(G62:L62) -> 0 | N62: =M62*N$9 -> 0 | O62: =M62*O$9 -> 0 | P62: =M62*P$9 -> 0 | Q62: =SUM(N62:P62)*Q$9 -> 0 | R62: =SUM(M62:Q62) -> 0 | T62: =SUM(N62:Q62)*$S$69 -> 0 | U62: =M62*$S$69 -> 0 | V62: =(K62+L62+Q62)*S$69 -> 0
A64: Summary Water Distribution | G64: =SUM(G11:G62) -> 12350 | H64: =SUM(H11:H62) -> 617.5 | I64: =SUM(I11:I62) -> 259.35 | J64: =SUM(J11:J62) -> 661.3425 | K64: =SUM(K11:K62) -> 1694.3595 | L64: =SUM(L11:L62) -> 1558.2552 | M64: =SUM(M11:M62) -> 17140.807 | N64: =SUM(N11:N62) -> 1319.8422 | ... R64: =SUM(R11:R62) -> 20101.025

Sheet CM Cost Estimating Worksheet
B1: Doyon Utilities, LLC
B2: Project Estimating Worksheet
B3: FTW 336A Aircraft Parts Storage RFP FWA-09-021
A5: Asset Type X= linear | B5: Item | C5: Year Inst | D5: Qty | F5: Unit Cost | G5: RCN | H5: Contractors Mark-ups % | M5: Contractors Mark-ups $ | R5: RCN (Total Installed) | S5: Engineering Services % | W5: Engineering Services $'s | AA5: RCN (Total w. Enginering) | AB5: Design Life | AC5: RCNLD | AD5: Historical Inflation Index | AE5: OC | AF5: OCLD | AG5: RYN (Repl Year New) | AH5: Source | AI5: Notes | AJ5: RDL Repl. Design Life | AK5: MMC Major Maintenance Cost | AL5: MMY Major Maintenance Start Year | AM5: MMD Major Maintenance Program Duration (yrs) | AN5: Comments | AO5: Condition Rating (Poor, Fair, Good) | AP5: Condition Rating Comments | AQ5: Condition Rating (Poor, Fair, Good)
B6: Provide EDS engineering costs for the FTW 336A Aircraft parts Storage Building. | H6: Contingency | I6: Bonds & Insurance | J6: General Conditions | K6: Contractors G&A | L6: Contractors Profit | M6: Contingency | N6: Bonds & Insurance | O6: General Conditions | P6: Contractors G&A | Q6: Contractors Profit | S6: Studies & Pre-Design | T6: Design | U6: Services During Construction(3%) & Commissioning (2%) | V6: Fee's on Studies & Design | W6: Studies & Pre-Design | X6: Design | Y6: Services During Construction | Z6: Fee's on Studies & Design
B7: EDS | H7: 0.05 | I7: 0.02 | J7: 0.05 | K7: 0.122 | L7: 0.1 | S7: 0.05 | T7: 0.05 | U7: 0.05 | V7: 0.1
B9: Engineering EDS Area Lights & HBO Feed | C9: 2009 | D9: 1 | E9: ea | F9: 3500 | G9: =IF(ISERROR(F9*D9)," ",F9*D9) -> 3500 | H9: =H$7 -> 0.05 | I9: =I$7 -> 0.02 | J9: =J$7 -> 0.05 | K9: =K$7 -> 0.122 | L9: =L$7 -> 0.1 | M9: =G9*H9 -> 175 | N9: =(G9+M9)*I9 -> 73.5 | O9: =(G9+M9+N9)*J9 -> 187.425 | P9: =(G9+M9+N9+O9)*K9 -> 480.18285 | Q9: =(G9+M9+N9+O9+P9)*L9 -> 441.61079 | R9: =G9+SUM(M9:Q9) -> 4857.7186 | S9: =S$7 -> 0.05 | T9: =T$7 -> 0.05 | U9: =U$7 -> 0.05 | V9: =V$7 -> 0.1 | W9: =R9*S9 -> 242.88593 | X9: =R9*T9 -> 242.88593 | Y9: =R9*U9 -> 242.88593 | Z9: =(W9+X9)*V9 -> 48.577186 | AA9: =R9+SUM(W9:Z9) -> 5634.9536 | AB9: 50 | AC9: =IF(ISERROR(IF('Wainwright Summary'!$E$7-C9>AB9,0,(AB9-('Wainwright Summary'!$E$7-C9))/AB9)*AA9)," ",(IF('Wainwright Summary'!$E$7-C9>AB9,0,(AB9-('Wainwright Summary'!$E$7-C9))/AB9)*AA9)) -> 5747.6527 | AD9: =VLOOKUP(C9,'Inflation-OLD'!$A$6:$B$126,2)/VLOOKUP('Wainwright Summary'!$E$6,'Inflation-OLD'!$A$6:$B$126,2) -> 1.0404 | AE9: 0 | AF9: =IF(ISERROR((AC9/AA9)*AE9)," ",(AC9/AA9)*AE9) -> 0 | AG9: 2009 | AJ9: =AB9 -> 50
B10: Engineering EDS Building Service | C10: 2009 | D10: 1 | E10: ea | F10: 8750 | G10: 8850 | H10: =H$7 -> 0.05 | I10: =I$7 -> 0.02 | J10: =J$7 -> 0.05 | K10: =K$7 -> 0.122 | L10: =L$7 -> 0.1 | M10: =G10*H10 -> 442.5 | N10: =(G10+M10)*I10 -> 185.85 | O10: =(G10+M10+N10)*J10 -> 473.9175 | P10: =(G10+M10+N10+O10)*K10 -> 1214.1766 | Q10: =(G10+M10+N10+O10+P10)*L10 -> 1116.6444 | R10: =G10+SUM(M10:Q10) -> 12283.089 | S10: =S$7 -> 0.05 | T10: =T$7 -> 0.05 | U10: =U$7 -> 0.05 | V10: =V$7 -> 0.1 | W10: =R10*S10 -> 614.15443 | X10: =R10*T10 -> 614.15443 | Y10: =R10*U10 -> 614.15443 | Z10: =(W10+X10)*V10 -> 122.83089 | AA10: =R10+SUM(W10:Z10) -> 14248.383 | AB10: 50 | AC10: =IF(ISERROR(IF('Wainwright Summary'!$E$7-C10>AB10,0,(AB10-('Wainwright Summary'!$E$7-C10))/AB10)*AA10)," ",(IF('Wainwright Summary'!$E$7-C10>AB10,0,(AB10-('Wainwright Summary'!$E$7-C10))/AB10)*AA10)) -> 14533.35 | AD10: =VLOOKUP(C10,'Inflation-OLD'!$A$6:$B$126,2)/VLOOKUP('Wainwright Summary'!$E$6,'Inflation-OLD'!$A$6:$B$126,2) -> 1.0404 | AE10: 0 | AF10: =IF(ISERROR((AC10/AA10)*AE10)," ",(AC10/AA10)*AE10) -> 0 | AG10: 2009 | AJ10: =AB10 -> 50
B12: Total Phase 1 Project Cost | G12: =SUM(G9:G10) -> 12350 | R12: =SUM(R9:R10) -> 17140.807 | X12: Total CPM & Commissioning | Y12: =SUM(Y9:Y10) -> 857.04036 | AA12: =SUM(AA9:AA10) -> 19883.336
A147: *

Sheet Wainwright Electrical Dist
B4: Doyon Utilities, LLC
B5: Fort Wainwright Utility Inventory and Replacement Cost
B6: Fort Wainwright Electrical Distribution System
B8: Item | C8: Year Inst | D8: Quantity | F8: Unit Cost | G8: RCN | H8: Contractors Mark-ups % | M8: Contractors Mark-ups $ | R8: RCN (Total Installed) | S8: Engineering Services % | W8: Engineering Services $'s | AA8: RCN (Total w. Enginering) | AB8: Design Life | AC8: RCNLD | AD8: Historical Inflation Index | AE8: OC | AF8: OCLD | AG8: RYN (Repl Year New) | AH8: Source | AI8: Notes | AJ8: RDL Repl. Design Life | AK8: MMC Major Maintenance Cost | AL8: MMY Major Maintenance Start Year | AM8: MMD Major Maintenance Program Duration (yrs) | AN8: Comments | AO8: Condition Rating (Poor, Fair, Good) | AP8: Condition Rating Comments | AQ8: Condition Rating (Poor, Fair, Good)
H9: Contingency | I9: Bonds & Insurance | J9: General Conditions | K9: Contractors G&A | L9: Contractors Profit | M9: Contingency | N9: Bonds & Insurance | O9: General Conditions | P9: Contractors G&A | Q9: Contractors Profit | S9: Studies & Pre-Design | T9: Design | U9: Services During Construction (3%) & Commissioning (2%) >$150,000 | V9: Fee's on Studies & Design | W9: Studies & Pre-Design | X9: Design | Y9: Services During Construction | Z9: Fee's on Studies & Design
H10: 0.05 | I10: 0.02 | J10: 0.05 | K10: 0.122 | L10: 0.1 | S10: 0.077 | T10: 0.05 | U10: 0.05 | V10: 0.1
G11: =IF(ISERROR(F11*D11)," ",F11*D11)
B12: DISTRIBUTION SYSTEM | G12: =IF(ISERROR(F12*D12)," ",F12*D12)
B13: CANTONMENT AREA (NON-HOUSING) | G13: =IF(ISERROR(F13*D13)," ",F13*D13) | AC13: =IF(ISERROR(IF('Wainwright Summary'!$E$7-C13>AB13,0,(AB13-('Wainwright Summary'!$E$7-C13))/AB13)*G13)," ",(IF('Wainwright Summary'!$E$7-C13>AB13,0,(AB13-('Wainwright Summary'!$E$7-C13))/AB13)*G13)) | AE13: =IF(ISERROR(D13*F13*AD13), " ",D13*F13*AD13 ) | AF13: =IF(ISERROR((AC13/G13)*AE13)," ",(AC13/G13)*AE13) | AG13: =IF(ISERROR(C13+AB13)," ",(C13+AB13))
B14: Overhead Lines _ Replace All Overhead Facilities -(ECU4) | G14: =IF(ISERROR(F14*D14)," ",F14*D14) | AC14: =IF(ISERROR(IF('Wainwright Summary'!$E$7-C14>AB14,0,(AB14-('Wainwright Summary'!$E$7-C14))/AB14)*G14)," ",(IF('Wainwright Summary'!$E$7-C14>AB14,0,(AB14-('Wainwright Summary'!$E$7-C14))/AB14)*G14)) | AE14: =IF(ISERROR(D14*F14*AD14), " ",D14*F14*AD14 ) | AF14: =IF(ISERROR((AC14/G14)*AE14)," ",(AC14/G14)*AE14) | AG14: =IF(ISERROR(C14+AB14)," ",(C14+AB14))
B15: 3 Ph. - Open Wire, Large | C15: 1982 | D15: 46728 | E15: lf | F15: 33 | G15: =IF(ISERROR(F15*D15)," ",F15*D15) -> 1542024 | H15: =H$10 -> 0.05 | I15: =I$10 -> 0.02 | J15: =J$10 -> 0.05 | K15: =K$10 -> 0.122 | L15: =L$10 -> 0.1 | M15: =G15*H15 -> 77101.2 | N15: =(G15+M15)*I15 -> 32382.504 | O15: =(G15+M15+N15)*J15 -> 82575.385 | P15: =(G15+M15+N15+O15)*K15 -> 211558.14 | Q15: =(G15+M15+N15+O15+P15)*L15 -> 194564.12 | R15: =G15+SUM(M15:Q15) -> 2140205.3 | S15: =S$10 -> 0.077 | T15: =T$10 -> 0.05 | U15: =U$10 -> 0.05 | V15: =V$10 -> 0.1 | W15: =R15*S15 -> 164795.81 | X15: =R15*T15 -> 107010.27 | Y15: =R15*U15 -> 107010.27 | Z15: =(W15+X15)*V15 -> 27180.608 | AA15: =R15+SUM(W15:Z15) -> 2546202.3 | AB15: 50 | AC15: =IF(ISERROR(IF('Wainwright Summary'!$E$7-C15>AB15,0,(AB15-('Wainwright Summary'!$E$7-C15))/AB15)*G15)," ",(IF('Wainwright Summary'!$E$7-C15>AB15,0,(AB15-('Wainwright Summary'!$E$7-C15))/AB15)*AA15)) -> 1222177.1 | AD15: =VLOOKUP(C15,'Inflation-OLD'!$A$6:$B$126,2)/VLOOKUP('Wainwright Summary'!$E$6,'Inflation-OLD'!$A$6:$B$126,2) -> 0.54223993 | AE15: =IF(ISERROR(AA15*AD15), " ",AA15*AD15 ) -> 1380652.6 | AF15: =IF(ISERROR((AC15/AA15)*AE15)," ",(AC15/AA15)*AE15) -> 662713.23 | AG15: =IF(ISERROR(C15+AB15)," ",(C15+AB15)) -> 2032 | AJ15: =AB15 -> 50
B16: 3 Ph. - Open Wire, Small (yr 1) | C16: 1966 | D16: =172086.16/2 -> 86043.08 | E16: lf | F16: =31*1.064 -> 32.984 | G16: =IF(ISERROR(F16*D16)," ",F16*D16) -> 2838045 | H16: =H$10 -> 0.05 | I16: =I$10 -> 0.02 | J16: =J$10 -> 0.05 | K16: =K$10 -> 0.122 | L16: =L$10 -> 0.1 | M16: =G16*H16 -> 141902.25 | N16: =(G16+M16)*I16 -> 59598.944 | O16: =(G16+M16+N16)*J16 -> 151977.31 | P16: =(G16+M16+N16+O16)*K16 -> 389365.86 | Q16: =(G16+M16+N16+O16+P16)*L16 -> 358088.93 | R16: =G16+SUM(M16:Q16) -> 3938978.2 | S16: =S$10 -> 0.077 | T16: =T$10 -> 0.05 | U16: =U$10 -> 0.05 | V16: =V$10 -> 0.1 | W16: =R16*S16 -> 303301.32 | X16: =R16*T16 -> 196948.91 | Y16: =R16*U16 -> 196948.91 | Z16: =(W16+X16)*V16 -> 50025.024 | AA16: =R16+SUM(W16:Z16) -> 4686202.4 | AB16: 35 | AC16: =IF(ISERROR(IF('Wainwright Summary'!$E$7-C16>AB16,0,(AB16-('Wainwright Summary'!$E$7-C16))/AB16)*G16)," ",(IF('Wainwright Summary'!$E$7-C16>AB16,0,(AB16-('Wainwright Summary'!$E$7-C16))/AB16)*AA16)) -> 0 | AD16: =VLOOKUP(C16,'Inflation-OLD'!$A$6:$B$126,2)/VLOOKUP('Wainwright Summary'!$E$6,'Inflation-OLD'!$A$6:$B$126,2) -> 0.2003394 | AE16: =IF(ISERROR(AA16*AD16), " ",AA16*AD16 ) -> 938831 | AF16: =IF(ISERROR((AC16/AA16)*AE16)," ",(AC16/AA16)*AE16) -> 0 | AG16: 2008 | AJ16: 50 | AN16: ECU4
B17: 3 Ph. - Open Wire, Small (yr 2) | C17: 1966 | D17: =172086.16/2 -> 86043.08 | E17: lf | F17: =31*1.064 -> 32.984 | G17: =IF(ISERROR(F17*D17)," ",F17*D17) -> 2838045 | H17: =H$10 -> 0.05 | I17: =I$10 -> 0.02 | J17: =J$10 -> 0.05 | K17: =K$10 -> 0.122 | L17: =L$10 -> 0.1 | M17: =G17*H17 -> 141902.25 | N17: =(G17+M17)*I17 -> 59598.944 | O17: =(G17+M17+N17)*J17 -> 151977.31 | P17: =(G17+M17+N17+O17)*K17 -> 389365.86 | Q17: =(G17+M17+N17+O17+P17)*L17 -> 358088.93 | R17: =G17+SUM(M17:Q17) -> 3938978.2 | S17: =S$10 -> 0.077 | T17: =T$10 -> 0.05 | U17: =U$10 -> 0.05 | V17: =V$10 -> 0.1 | W17: =R17*S17 -> 303301.32 | X17: =R17*T17 -> 196948.91 | Y17: =R17*U17 -> 196948.91 | Z17: =(W17+X17)*V17 -> 50025.024 | AA17: =R17+SUM(W17:Z17) -> 4686202.4 | AB17: 35 | AC17: =IF(ISERROR(IF('Wainwright Summary'!$E$7-C17>AB17,0,(AB17-('Wainwright Summary'!$E$7-C17))/AB17)*G17)," ",(IF('Wainwright Summary'!$E$7-C17>AB17,0,(AB17-('Wainwright Summary'!$E$7-C17))/AB17)*AA17)) -> 0 | AD17: =VLOOKUP(C17,'Inflation-OLD'!$A$6:$B$126,2)/VLOOKUP('Wainwright Summary'!$E$6,'Inflation-OLD'!$A$6:$B$126,2) -> 0.2003394 | AE17: =IF(ISERROR(AA17*AD17), " ",AA17*AD17 ) -> 938831 | AF17: =IF(ISERROR((AC17/AA17)*AE17)," ",(AC17/AA17)*AE17) -> 0 | AG17: 2009 | AJ17: 50 | AN17: ECU4
B18: 1 Ph. - Open Wire | C18: 1975 | D18: 18216 | E18: lf | F18: =26*1.064 -> 27.664 | G18: =IF(ISERROR(F18*D18)," ",F18*D18) -> 503927.42 | H18: =H$10 -> 0.05 | I18: =I$10 -> 0.02 | J18: =J$10 -> 0.05 | K18: =K$10 -> 0.122 | L18: =L$10 -> 0.1 | M18: =G18*H18 -> 25196.371 | N18: =(G18+M18)*I18 -> 10582.476 | O18: =(G18+M18+N18)*J18 -> 26985.314 | P18: =(G18+M18+N18+O18)*K18 -> 69136.373 | Q18: =(G18+M18+N18+O18+P18)*L18 -> 63582.796 | R18: =G18+SUM(M18:Q18) -> 699410.75 | S18: =S$10 -> 0.077 | T18: =T$10 -> 0.05 | U18: =U$10 -> 0.05 | V18: =V$10 -> 0.1 | W18: =R18*S18 -> 53854.628 | X18: =R18*T18 -> 34970.538 | Y18: =R18*U18 -> 34970.538 | Z18: =(W18+X18)*V18 -> 8882.5166 | AA18: =R18+SUM(W18:Z18) -> 832088.97 | AB18: 35 | AC18: =IF(ISERROR(IF('Wainwright Summary'!$E$7-C18>AB18,0,(AB18-('Wainwright Summary'!$E$7-C18))/AB18)*G18)," ",(IF('Wainwright Summary'!$E$7-C18>AB18,0,(AB18-('Wainwright Summary'!$E$7-C18))/AB18)*AA18)) -> 47547.941 | AD18: =VLOOKUP(C18,'Inflation-OLD'!$A$6:$B$126,2)/VLOOKUP('Wainwright Summary'!$E$6,'Inflation-OLD'!$A$6:$B$126,2) -> 0.3204444 | AE18: =IF(ISERROR(AA18*AD18), " ",AA18*AD18 ) -> 266638.25 | AF18: =IF(ISERROR((AC18/AA18)*AE18)," ",(AC18/AA18)*AE18) -> 15236.471 | AG18: 2008 | AJ18: 50 | AN18: ECU4
B19: Gang Operated Air Break Switch | C19: 1985 | D19: 40 | E19: ea | F19: 1000 | G19: =IF(ISERROR(F19*D19)," ",F19*D19) -> 40000 | H19: =H$10 -> 0.05 | I19: =I$10 -> 0.02 | J19: =J$10 -> 0.05 | K19: =K$10 -> 0.122 | L19: =L$10 -> 0.1 | M19: =G19*H19 -> 2000 | N19: =(G19+M19)*I19 -> 840 | O19: =(G19+M19+N19)*J19 -> 2142 | P19: =(G19+M19+N19+O19)*K19 -> 5487.804 | Q19: =(G19+M19+N19+O19+P19)*L19 -> 5046.9804 | R19: =G19+SUM(M19:Q19) -> 55516.784 | S19: =S$10 -> 0.077 | T19: =T$10 -> 0.05 | U19: 0.03 | V19: =V$10 -> 0.1 | W19: =R19*S19 -> 4274.7924 | X19: =R19*T19 -> 2775.8392 | Y19: =R19*U19 -> 1665.5035 | Z19: =(W19+X19)*V19 -> 705.06316 | AA19: =R19+SUM(W19:Z19) -> 64937.983 | AB19: 35 | AC19: =IF(ISERROR(IF('Wainwright Summary'!$E$7-C19>AB19,0,(AB19-('Wainwright Summary'!$E$7-C19))/AB19)*G19)," ",(IF('Wainwright Summary'!$E$7-C19>AB19,0,(AB19-('Wainwright Summary'!$E$7-C19))/AB19)*AA19)) -> 22264.451 | AD19: =VLOOKUP(C19,'Inflation-OLD'!$A$6:$B$126,2)/VLOOKUP('Wainwright Summary'!$E$6,'Inflation-OLD'!$A$6:$B$126,2) -> 0.60685494 | AE19: =IF(ISERROR(AA19*AD19), " ",AA19*AD19 ) -> 39407.936 | AF19: =IF(ISERROR((AC19/AA19)*AE19)," ",(AC19/AA19)*AE19) -> 13511.292 | AG19: 2008 | AJ19: 50 | AN19: ECU4
B20: Secondary | C20: 1979 | D20: 61300.8 | E20: lf | F20: =16*1.064 -> 17.024 | G20: =IF(ISERROR(F20*D20)," ",F20*D20) -> 1043584.8 | H20: =H$10 -> 0.05 | I20: =I$10 -> 0.02 | J20: =J$10 -> 0.05 | K20: =K$10 -> 0.122 | L20: =L$10 -> 0.1 | M20: =G20*H20 -> 52179.241 | N20: =(G20+M20)*I20 -> 21915.281 | O20: =(G20+M20+N20)*J20 -> 55883.967 | P20: =(G20+M20+N20+O20)*K20 -> 143174.72 | Q20: =(G20+M20+N20+O20+P20)*L20 -> 131673.8 | R20: =G20+SUM(M20:Q20) -> 1448411.8 | S20: =S$10 -> 0.077 | T20: =T$10 -> 0.05 | U20: =U$10 -> 0.05 | V20: =V$10 -> 0.1 | W20: =R20*S20 -> 111527.71 | X20: =R20*T20 -> 72420.592 | Y20: =R20*U20 -> 72420.592 | Z20: =(W20+X20)*V20 -> 18394.83 | AA20: =R20+SUM(W20:Z20) -> 1723175.6 | AB20: 35 | AC20: =IF(ISERROR(IF('Wainwright Summary'!$E$7-C20>AB20,0,(AB20-('Wainwright Summary'!$E$7-C20))/AB20)*G20)," ",(IF('Wainwright Summary'!$E$7-C20>AB20,0,(AB20-('Wainwright Summary'!$E$7-C20))/AB20)*AA20)) -> 295401.52 | AD20: =VLOOKUP(C20,'Inflation-OLD'!$A$6:$B$126,2)/VLOOKUP('Wainwright Summary'!$E$6,'Inflation-OLD'!$A$6:$B$126,2) -> 0.42632751 | AE20: =IF(ISERROR(AA20*AD20), " ",AA20*AD20 ) -> 734637.15 | AF20: =IF(ISERROR((AC20/AA20)*AE20)," ",(AC20/AA20)*AE20) -> 125937.8 | AG20: 2008 | AJ20: 50 | AN20: ECU4
G21: =IF(ISERROR(F21*D21)," ",F21*D21) | AC21: =IF(ISERROR(IF('Wainwright Summary'!$E$7-C21>AB21,0,(AB21-('Wainwright Summary'!$E$7-C21))/AB21)*G21)," ",(IF('Wainwright Summary'!$E$7-C21>AB21,0,(AB21-('Wainwright Summary'!$E$7-C21))/AB21)*G21)) | AE21: =IF(ISERROR(D21*F21*AD21), " ",D21*F21*AD21 ) | AF21: =IF(ISERROR((AC21/G21)*AE21)," ",(AC21/G21)*AE21) | AG21: =IF(ISERROR(C21+AB21)," ",(C21+AB21)) | AJ21: =AB21
